[ERROR] [2019-05-12 23:10:28,212] [log] [log_response] [17182][line:228] Internal Server Error: /test
Traceback (most recent call last):
  File "/home/damon96/.virtualenvs/XiAnMini/lib/python3.6/site-packages/django/core/handlers/exception.py", line 34, in inner
    response = get_response(request)
  File "/home/damon96/.virtualenvs/XiAnMini/lib/python3.6/site-packages/django/core/handlers/base.py", line 126, in _get_response
    response = self.process_exception_by_middleware(e, request)
  File "/home/damon96/.virtualenvs/XiAnMini/lib/python3.6/site-packages/django/core/handlers/base.py", line 124, in _get_response
    response = wrapped_callback(request, *callback_args, **callback_kwargs)
  File "/home/damon96/.virtualenvs/XiAnMini/lib/python3.6/site-packages/django/views/decorators/csrf.py", line 54, in wrapped_view
    return view_func(*args, **kwargs)
  File "/home/damon96/PycharmProjects/XiAn/XiAn/views.py", line 26, in test
    user_obj = getattr(getattr(User, "objects"), "get")(**{"id": userid})
  File "/home/damon96/.virtualenvs/XiAnMini/lib/python3.6/site-packages/django/db/models/manager.py", line 82, in manager_method
    return getattr(self.get_queryset(), name)(*args, **kwargs)
  File "/home/damon96/.virtualenvs/XiAnMini/lib/python3.6/site-packages/django/db/models/query.py", line 399, in get
    self.model._meta.object_name
users.models.User.DoesNotExist: User matching query does not exist.
[ERROR] [2019-05-12 23:11:46,355] [log] [log_response] [17438][line:228] Internal Server Error: /test
Traceback (most recent call last):
  File "/home/damon96/.virtualenvs/XiAnMini/lib/python3.6/site-packages/django/core/handlers/exception.py", line 34, in inner
    response = get_response(request)
  File "/home/damon96/.virtualenvs/XiAnMini/lib/python3.6/site-packages/django/core/handlers/base.py", line 126, in _get_response
    response = self.process_exception_by_middleware(e, request)
  File "/home/damon96/.virtualenvs/XiAnMini/lib/python3.6/site-packages/django/core/handlers/base.py", line 124, in _get_response
    response = wrapped_callback(request, *callback_args, **callback_kwargs)
  File "/home/damon96/.virtualenvs/XiAnMini/lib/python3.6/site-packages/django/views/decorators/csrf.py", line 54, in wrapped_view
    return view_func(*args, **kwargs)
  File "/home/damon96/PycharmProjects/XiAn/XiAn/views.py", line 26, in test
    token = jwt_login(user_obj, request, expire=3600)
  File "/home/damon96/PycharmProjects/XiAn/XiAn/django_jwt_session_auth.py", line 227, in jwt_login
    user_to_payload_handler = import_string(jwt_settings['USER_TO_PAYLOAD'])
  File "/home/damon96/.virtualenvs/XiAnMini/lib/python3.6/site-packages/django/utils/module_loading.py", line 17, in import_string
    module = import_module(module_path)
  File "/home/damon96/.virtualenvs/XiAnMini/lib/python3.6/importlib/__init__.py", line 126, in import_module
    return _bootstrap._gcd_import(name[level:], package, level)
  File "<frozen importlib._bootstrap>", line 994, in _gcd_import
  File "<frozen importlib._bootstrap>", line 971, in _find_and_load
  File "<frozen importlib._bootstrap>", line 955, in _find_and_load_unlocked
  File "<frozen importlib._bootstrap>", line 665, in _load_unlocked
  File "<frozen importlib._bootstrap_external>", line 678, in exec_module
  File "<frozen importlib._bootstrap>", line 219, in _call_with_frames_removed
  File "/home/damon96/PycharmProjects/XiAn/XiAn/utils.py", line 9, in <module>
    from backend.models import User
ModuleNotFoundError: No module named 'backend'
[ERROR] [2019-05-12 23:20:20,643] [log] [log_response] [18031][line:228] Internal Server Error: /api/updateUserInfo
Traceback (most recent call last):
  File "/home/damon96/.virtualenvs/XiAnMini/lib/python3.6/site-packages/rest_framework/request.py", line 412, in __getattr__
    return getattr(self._request, attr)
AttributeError: 'WSGIRequest' object has no attribute 'jwt_user'

During handling of the above exception, another exception occurred:

Traceback (most recent call last):
  File "/home/damon96/.virtualenvs/XiAnMini/lib/python3.6/site-packages/django/core/handlers/exception.py", line 34, in inner
    response = get_response(request)
  File "/home/damon96/.virtualenvs/XiAnMini/lib/python3.6/site-packages/django/core/handlers/base.py", line 126, in _get_response
    response = self.process_exception_by_middleware(e, request)
  File "/home/damon96/.virtualenvs/XiAnMini/lib/python3.6/site-packages/django/core/handlers/base.py", line 124, in _get_response
    response = wrapped_callback(request, *callback_args, **callback_kwargs)
  File "/home/damon96/.virtualenvs/XiAnMini/lib/python3.6/site-packages/django/views/decorators/csrf.py", line 54, in wrapped_view
    return view_func(*args, **kwargs)
  File "/home/damon96/.virtualenvs/XiAnMini/lib/python3.6/site-packages/django/views/decorators/csrf.py", line 54, in wrapped_view
    return view_func(*args, **kwargs)
  File "/home/damon96/.virtualenvs/XiAnMini/lib/python3.6/site-packages/django/views/generic/base.py", line 68, in view
    return self.dispatch(request, *args, **kwargs)
  File "/home/damon96/.virtualenvs/XiAnMini/lib/python3.6/site-packages/rest_framework/views.py", line 495, in dispatch
    response = self.handle_exception(exc)
  File "/home/damon96/.virtualenvs/XiAnMini/lib/python3.6/site-packages/rest_framework/views.py", line 455, in handle_exception
    self.raise_uncaught_exception(exc)
  File "/home/damon96/.virtualenvs/XiAnMini/lib/python3.6/site-packages/rest_framework/views.py", line 492, in dispatch
    response = handler(request, *args, **kwargs)
  File "/home/damon96/.virtualenvs/XiAnMini/lib/python3.6/site-packages/rest_framework/decorators.py", line 55, in handler
    return func(*args, **kwargs)
  File "/home/damon96/PycharmProjects/XiAn/apps/users/views.py", line 25, in updateUserInfo
    userid = request.jwt_user.id
  File "/home/damon96/.virtualenvs/XiAnMini/lib/python3.6/site-packages/rest_framework/request.py", line 414, in __getattr__
    return self.__getattribute__(attr)
AttributeError: 'Request' object has no attribute 'jwt_user'
[ERROR] [2019-05-12 23:20:36,405] [log] [log_response] [18031][line:228] Internal Server Error: /api/updateUserInfo
Traceback (most recent call last):
  File "/home/damon96/.virtualenvs/XiAnMini/lib/python3.6/site-packages/rest_framework/request.py", line 412, in __getattr__
    return getattr(self._request, attr)
AttributeError: 'WSGIRequest' object has no attribute 'jwt_user'

During handling of the above exception, another exception occurred:

Traceback (most recent call last):
  File "/home/damon96/.virtualenvs/XiAnMini/lib/python3.6/site-packages/django/core/handlers/exception.py", line 34, in inner
    response = get_response(request)
  File "/home/damon96/.virtualenvs/XiAnMini/lib/python3.6/site-packages/django/core/handlers/base.py", line 126, in _get_response
    response = self.process_exception_by_middleware(e, request)
  File "/home/damon96/.virtualenvs/XiAnMini/lib/python3.6/site-packages/django/core/handlers/base.py", line 124, in _get_response
    response = wrapped_callback(request, *callback_args, **callback_kwargs)
  File "/home/damon96/.virtualenvs/XiAnMini/lib/python3.6/site-packages/django/views/decorators/csrf.py", line 54, in wrapped_view
    return view_func(*args, **kwargs)
  File "/home/damon96/.virtualenvs/XiAnMini/lib/python3.6/site-packages/django/views/decorators/csrf.py", line 54, in wrapped_view
    return view_func(*args, **kwargs)
  File "/home/damon96/.virtualenvs/XiAnMini/lib/python3.6/site-packages/django/views/generic/base.py", line 68, in view
    return self.dispatch(request, *args, **kwargs)
  File "/home/damon96/.virtualenvs/XiAnMini/lib/python3.6/site-packages/rest_framework/views.py", line 495, in dispatch
    response = self.handle_exception(exc)
  File "/home/damon96/.virtualenvs/XiAnMini/lib/python3.6/site-packages/rest_framework/views.py", line 455, in handle_exception
    self.raise_uncaught_exception(exc)
  File "/home/damon96/.virtualenvs/XiAnMini/lib/python3.6/site-packages/rest_framework/views.py", line 492, in dispatch
    response = handler(request, *args, **kwargs)
  File "/home/damon96/.virtualenvs/XiAnMini/lib/python3.6/site-packages/rest_framework/decorators.py", line 55, in handler
    return func(*args, **kwargs)
  File "/home/damon96/PycharmProjects/XiAn/apps/users/views.py", line 25, in updateUserInfo
    userid = request.jwt_user.id
  File "/home/damon96/.virtualenvs/XiAnMini/lib/python3.6/site-packages/rest_framework/request.py", line 414, in __getattr__
    return self.__getattribute__(attr)
AttributeError: 'Request' object has no attribute 'jwt_user'
[ERROR] [2019-05-12 23:23:09,798] [log] [log_response] [18240][line:228] Internal Server Error: /api/updateUserInfo
Traceback (most recent call last):
  File "/home/damon96/.virtualenvs/XiAnMini/lib/python3.6/site-packages/rest_framework/request.py", line 412, in __getattr__
    return getattr(self._request, attr)
AttributeError: 'WSGIRequest' object has no attribute 'jwt_user'

During handling of the above exception, another exception occurred:

Traceback (most recent call last):
  File "/home/damon96/.virtualenvs/XiAnMini/lib/python3.6/site-packages/django/core/handlers/exception.py", line 34, in inner
    response = get_response(request)
  File "/home/damon96/.virtualenvs/XiAnMini/lib/python3.6/site-packages/django/core/handlers/base.py", line 126, in _get_response
    response = self.process_exception_by_middleware(e, request)
  File "/home/damon96/.virtualenvs/XiAnMini/lib/python3.6/site-packages/django/core/handlers/base.py", line 124, in _get_response
    response = wrapped_callback(request, *callback_args, **callback_kwargs)
  File "/home/damon96/.virtualenvs/XiAnMini/lib/python3.6/site-packages/django/views/decorators/csrf.py", line 54, in wrapped_view
    return view_func(*args, **kwargs)
  File "/home/damon96/.virtualenvs/XiAnMini/lib/python3.6/site-packages/django/views/decorators/csrf.py", line 54, in wrapped_view
    return view_func(*args, **kwargs)
  File "/home/damon96/.virtualenvs/XiAnMini/lib/python3.6/site-packages/django/views/generic/base.py", line 68, in view
    return self.dispatch(request, *args, **kwargs)
  File "/home/damon96/.virtualenvs/XiAnMini/lib/python3.6/site-packages/rest_framework/views.py", line 495, in dispatch
    response = self.handle_exception(exc)
  File "/home/damon96/.virtualenvs/XiAnMini/lib/python3.6/site-packages/rest_framework/views.py", line 455, in handle_exception
    self.raise_uncaught_exception(exc)
  File "/home/damon96/.virtualenvs/XiAnMini/lib/python3.6/site-packages/rest_framework/views.py", line 492, in dispatch
    response = handler(request, *args, **kwargs)
  File "/home/damon96/.virtualenvs/XiAnMini/lib/python3.6/site-packages/rest_framework/decorators.py", line 55, in handler
    return func(*args, **kwargs)
  File "/home/damon96/PycharmProjects/XiAn/apps/users/views.py", line 25, in updateUserInfo
    userid = request.jwt_user.id
  File "/home/damon96/.virtualenvs/XiAnMini/lib/python3.6/site-packages/rest_framework/request.py", line 414, in __getattr__
    return self.__getattribute__(attr)
AttributeError: 'Request' object has no attribute 'jwt_user'
[ERROR] [2019-05-12 23:23:38,166] [log] [log_response] [18270][line:228] Internal Server Error: /api/updateUserInfo
Traceback (most recent call last):
  File "/home/damon96/.virtualenvs/XiAnMini/lib/python3.6/site-packages/rest_framework/request.py", line 412, in __getattr__
    return getattr(self._request, attr)
AttributeError: 'WSGIRequest' object has no attribute 'jwt_user'

During handling of the above exception, another exception occurred:

Traceback (most recent call last):
  File "/home/damon96/.virtualenvs/XiAnMini/lib/python3.6/site-packages/django/core/handlers/exception.py", line 34, in inner
    response = get_response(request)
  File "/home/damon96/.virtualenvs/XiAnMini/lib/python3.6/site-packages/django/core/handlers/base.py", line 126, in _get_response
    response = self.process_exception_by_middleware(e, request)
  File "/home/damon96/.virtualenvs/XiAnMini/lib/python3.6/site-packages/django/core/handlers/base.py", line 124, in _get_response
    response = wrapped_callback(request, *callback_args, **callback_kwargs)
  File "/home/damon96/.virtualenvs/XiAnMini/lib/python3.6/site-packages/django/views/decorators/csrf.py", line 54, in wrapped_view
    return view_func(*args, **kwargs)
  File "/home/damon96/.virtualenvs/XiAnMini/lib/python3.6/site-packages/django/views/decorators/csrf.py", line 54, in wrapped_view
    return view_func(*args, **kwargs)
  File "/home/damon96/.virtualenvs/XiAnMini/lib/python3.6/site-packages/django/views/generic/base.py", line 68, in view
    return self.dispatch(request, *args, **kwargs)
  File "/home/damon96/.virtualenvs/XiAnMini/lib/python3.6/site-packages/rest_framework/views.py", line 495, in dispatch
    response = self.handle_exception(exc)
  File "/home/damon96/.virtualenvs/XiAnMini/lib/python3.6/site-packages/rest_framework/views.py", line 455, in handle_exception
    self.raise_uncaught_exception(exc)
  File "/home/damon96/.virtualenvs/XiAnMini/lib/python3.6/site-packages/rest_framework/views.py", line 492, in dispatch
    response = handler(request, *args, **kwargs)
  File "/home/damon96/.virtualenvs/XiAnMini/lib/python3.6/site-packages/rest_framework/decorators.py", line 55, in handler
    return func(*args, **kwargs)
  File "/home/damon96/PycharmProjects/XiAn/apps/users/views.py", line 25, in updateUserInfo
    userid = request.jwt_user.id
  File "/home/damon96/.virtualenvs/XiAnMini/lib/python3.6/site-packages/rest_framework/request.py", line 414, in __getattr__
    return self.__getattribute__(attr)
AttributeError: 'Request' object has no attribute 'jwt_user'
[WARNING] [2019-05-12 23:30:25,651] [log] [log_response] [18661][line:228] Not Found: /
[ERROR] [2019-05-12 23:31:08,173] [log] [log_response] [18661][line:228] Internal Server Error: /api/updateUserInfo
Traceback (most recent call last):
  File "/home/damon96/.virtualenvs/XiAnMini/lib/python3.6/site-packages/rest_framework/request.py", line 412, in __getattr__
    return getattr(self._request, attr)
AttributeError: 'WSGIRequest' object has no attribute 'jwt_user'

During handling of the above exception, another exception occurred:

Traceback (most recent call last):
  File "/home/damon96/.virtualenvs/XiAnMini/lib/python3.6/site-packages/django/core/handlers/exception.py", line 34, in inner
    response = get_response(request)
  File "/home/damon96/.virtualenvs/XiAnMini/lib/python3.6/site-packages/django/core/handlers/base.py", line 126, in _get_response
    response = self.process_exception_by_middleware(e, request)
  File "/home/damon96/.virtualenvs/XiAnMini/lib/python3.6/site-packages/django/core/handlers/base.py", line 124, in _get_response
    response = wrapped_callback(request, *callback_args, **callback_kwargs)
  File "/home/damon96/.virtualenvs/XiAnMini/lib/python3.6/site-packages/django/views/decorators/csrf.py", line 54, in wrapped_view
    return view_func(*args, **kwargs)
  File "/home/damon96/.virtualenvs/XiAnMini/lib/python3.6/site-packages/django/views/decorators/csrf.py", line 54, in wrapped_view
    return view_func(*args, **kwargs)
  File "/home/damon96/.virtualenvs/XiAnMini/lib/python3.6/site-packages/django/views/generic/base.py", line 68, in view
    return self.dispatch(request, *args, **kwargs)
  File "/home/damon96/.virtualenvs/XiAnMini/lib/python3.6/site-packages/rest_framework/views.py", line 495, in dispatch
    response = self.handle_exception(exc)
  File "/home/damon96/.virtualenvs/XiAnMini/lib/python3.6/site-packages/rest_framework/views.py", line 455, in handle_exception
    self.raise_uncaught_exception(exc)
  File "/home/damon96/.virtualenvs/XiAnMini/lib/python3.6/site-packages/rest_framework/views.py", line 492, in dispatch
    response = handler(request, *args, **kwargs)
  File "/home/damon96/.virtualenvs/XiAnMini/lib/python3.6/site-packages/rest_framework/decorators.py", line 55, in handler
    return func(*args, **kwargs)
  File "/home/damon96/PycharmProjects/XiAn/apps/users/views.py", line 20, in updateUserInfo
    userid = request.jwt_user.id
  File "/home/damon96/.virtualenvs/XiAnMini/lib/python3.6/site-packages/rest_framework/request.py", line 414, in __getattr__
    return self.__getattribute__(attr)
AttributeError: 'Request' object has no attribute 'jwt_user'
[ERROR] [2019-05-12 23:33:13,649] [log] [log_response] [18871][line:228] Internal Server Error: /api/updateUserInfo
Traceback (most recent call last):
  File "/home/damon96/.virtualenvs/XiAnMini/lib/python3.6/site-packages/rest_framework/request.py", line 412, in __getattr__
    return getattr(self._request, attr)
AttributeError: 'WSGIRequest' object has no attribute 'jwt_user'

During handling of the above exception, another exception occurred:

Traceback (most recent call last):
  File "/home/damon96/.virtualenvs/XiAnMini/lib/python3.6/site-packages/django/core/handlers/exception.py", line 34, in inner
    response = get_response(request)
  File "/home/damon96/.virtualenvs/XiAnMini/lib/python3.6/site-packages/django/core/handlers/base.py", line 126, in _get_response
    response = self.process_exception_by_middleware(e, request)
  File "/home/damon96/.virtualenvs/XiAnMini/lib/python3.6/site-packages/django/core/handlers/base.py", line 124, in _get_response
    response = wrapped_callback(request, *callback_args, **callback_kwargs)
  File "/home/damon96/.virtualenvs/XiAnMini/lib/python3.6/site-packages/django/views/decorators/csrf.py", line 54, in wrapped_view
    return view_func(*args, **kwargs)
  File "/home/damon96/.virtualenvs/XiAnMini/lib/python3.6/site-packages/django/views/decorators/csrf.py", line 54, in wrapped_view
    return view_func(*args, **kwargs)
  File "/home/damon96/.virtualenvs/XiAnMini/lib/python3.6/site-packages/django/views/generic/base.py", line 68, in view
    return self.dispatch(request, *args, **kwargs)
  File "/home/damon96/.virtualenvs/XiAnMini/lib/python3.6/site-packages/rest_framework/views.py", line 495, in dispatch
    response = self.handle_exception(exc)
  File "/home/damon96/.virtualenvs/XiAnMini/lib/python3.6/site-packages/rest_framework/views.py", line 455, in handle_exception
    self.raise_uncaught_exception(exc)
  File "/home/damon96/.virtualenvs/XiAnMini/lib/python3.6/site-packages/rest_framework/views.py", line 492, in dispatch
    response = handler(request, *args, **kwargs)
  File "/home/damon96/.virtualenvs/XiAnMini/lib/python3.6/site-packages/rest_framework/decorators.py", line 55, in handler
    return func(*args, **kwargs)
  File "/home/damon96/PycharmProjects/XiAn/apps/users/views.py", line 20, in updateUserInfo
    userid = request.jwt_user.id
  File "/home/damon96/.virtualenvs/XiAnMini/lib/python3.6/site-packages/rest_framework/request.py", line 414, in __getattr__
    return self.__getattribute__(attr)
AttributeError: 'Request' object has no attribute 'jwt_user'
[INFO] [2019-05-12 23:34:04,329] [views] [updateUserInfo] [18983][line:25] 此时的userinfo为{'userid': 1, 'activity_name': 'jifu', 'mission_name': 'jifu', 'invite_id': 'jifu-105c4948f13d129f6373ffc518a58496', 'phone_number': '15717929717', 'orderId': 'AQY20190228173355580331', 'resultCode': '200', 'card_type': 'KK00_VJIA', 'cashingCode': '9PRK943LQIMGW4U0'}
[ERROR] [2019-05-12 23:34:04,329] [tasks] [updateUserInfoTask] [18983][line:69] 更新用户信息时报错'Settings' object has no attribute 'ENCRYPT_FIELDS'
[INFO] [2019-05-12 23:34:44,942] [views] [updateUserInfo] [18983][line:25] 此时的userinfo为{'userid': 1, 'activity_name': 'jifu', 'mission_name': 'jifu', 'invite_id': 'jifu-105c4948f13d129f6373ffc518a58496', 'phone_number': '15717929717', 'orderId': 'AQY20190228173355580331', 'resultCode': '200', 'card_type': 'KK00_VJIA', 'cashingCode': '9PRK943LQIMGW4U0'}
[ERROR] [2019-05-12 23:34:44,942] [tasks] [updateUserInfoTask] [18983][line:69] 更新用户信息时报错'Settings' object has no attribute 'ENCRYPT_FIELDS'
[WARNING] [2019-05-18 13:41:13,719] [log] [log_response] [8646][line:228] Not Found: /favicon.ico
[WARNING] [2019-05-18 13:59:17,902] [log] [log_response] [10820][line:228] Not Found: /favicon.ico
[WARNING] [2019-05-18 14:16:10,559] [log] [log_response] [12284][line:228] Not Found: /media/
[WARNING] [2019-05-18 14:16:47,601] [log] [log_response] [12284][line:228] Not Found: /xadmin/users/company/1/update/1111111/media/company/ueditor/v2-7453eed9311d1c667d993dc5011fca6e_r_20190512205455_771.jpg
[ERROR] [2019-05-18 14:32:06,395] [log] [log_response] [13927][line:228] Internal Server Error: /api/proList
Traceback (most recent call last):
  File "/home/damon96/.virtualenvs/XiAnMini/lib/python3.6/site-packages/django/core/handlers/exception.py", line 34, in inner
    response = get_response(request)
  File "/home/damon96/.virtualenvs/XiAnMini/lib/python3.6/site-packages/django/core/handlers/base.py", line 126, in _get_response
    response = self.process_exception_by_middleware(e, request)
  File "/home/damon96/.virtualenvs/XiAnMini/lib/python3.6/site-packages/django/core/handlers/base.py", line 124, in _get_response
    response = wrapped_callback(request, *callback_args, **callback_kwargs)
  File "/home/damon96/.virtualenvs/XiAnMini/lib/python3.6/site-packages/django/views/decorators/csrf.py", line 54, in wrapped_view
    return view_func(*args, **kwargs)
  File "/home/damon96/.virtualenvs/XiAnMini/lib/python3.6/site-packages/django/views/decorators/csrf.py", line 54, in wrapped_view
    return view_func(*args, **kwargs)
  File "/home/damon96/.virtualenvs/XiAnMini/lib/python3.6/site-packages/django/views/generic/base.py", line 68, in view
    return self.dispatch(request, *args, **kwargs)
  File "/home/damon96/.virtualenvs/XiAnMini/lib/python3.6/site-packages/rest_framework/views.py", line 495, in dispatch
    response = self.handle_exception(exc)
  File "/home/damon96/.virtualenvs/XiAnMini/lib/python3.6/site-packages/rest_framework/views.py", line 455, in handle_exception
    self.raise_uncaught_exception(exc)
  File "/home/damon96/.virtualenvs/XiAnMini/lib/python3.6/site-packages/rest_framework/views.py", line 492, in dispatch
    response = handler(request, *args, **kwargs)
  File "/home/damon96/.virtualenvs/XiAnMini/lib/python3.6/site-packages/rest_framework/decorators.py", line 55, in handler
    return func(*args, **kwargs)
  File "/home/damon96/PycharmProjects/XiAn/apps/projects/views.py", line 16, in proList
    project_qs = Project.objects.filter(**query_params)
  File "/home/damon96/.virtualenvs/XiAnMini/lib/python3.6/site-packages/django/db/models/manager.py", line 82, in manager_method
    return getattr(self.get_queryset(), name)(*args, **kwargs)
  File "/home/damon96/.virtualenvs/XiAnMini/lib/python3.6/site-packages/django/db/models/query.py", line 841, in filter
    return self._filter_or_exclude(False, *args, **kwargs)
  File "/home/damon96/.virtualenvs/XiAnMini/lib/python3.6/site-packages/django/db/models/query.py", line 859, in _filter_or_exclude
    clone.query.add_q(Q(*args, **kwargs))
  File "/home/damon96/.virtualenvs/XiAnMini/lib/python3.6/site-packages/django/db/models/sql/query.py", line 1263, in add_q
    clause, _ = self._add_q(q_object, self.used_aliases)
  File "/home/damon96/.virtualenvs/XiAnMini/lib/python3.6/site-packages/django/db/models/sql/query.py", line 1287, in _add_q
    split_subq=split_subq,
  File "/home/damon96/.virtualenvs/XiAnMini/lib/python3.6/site-packages/django/db/models/sql/query.py", line 1225, in build_filter
    condition = self.build_lookup(lookups, col, value)
  File "/home/damon96/.virtualenvs/XiAnMini/lib/python3.6/site-packages/django/db/models/sql/query.py", line 1096, in build_lookup
    lookup = lookup_class(lhs, rhs)
  File "/home/damon96/.virtualenvs/XiAnMini/lib/python3.6/site-packages/django/db/models/lookups.py", line 20, in __init__
    self.rhs = self.get_prep_lookup()
  File "/home/damon96/.virtualenvs/XiAnMini/lib/python3.6/site-packages/django/db/models/lookups.py", line 70, in get_prep_lookup
    return self.lhs.output_field.get_prep_value(self.rhs)
  File "/home/damon96/.virtualenvs/XiAnMini/lib/python3.6/site-packages/django/db/models/fields/__init__.py", line 1018, in get_prep_value
    return self.to_python(value)
  File "/home/damon96/.virtualenvs/XiAnMini/lib/python3.6/site-packages/django/db/models/fields/__init__.py", line 1011, in to_python
    params={'value': value},
django.core.exceptions.ValidationError: ['’true‘ 必须为 True 或者 False。']
[ERROR] [2019-05-18 14:34:41,978] [log] [log_response] [14085][line:228] Internal Server Error: /api/proList
Traceback (most recent call last):
  File "/home/damon96/.virtualenvs/XiAnMini/lib/python3.6/site-packages/django/core/handlers/exception.py", line 34, in inner
    response = get_response(request)
  File "/home/damon96/.virtualenvs/XiAnMini/lib/python3.6/site-packages/django/core/handlers/base.py", line 126, in _get_response
    response = self.process_exception_by_middleware(e, request)
  File "/home/damon96/.virtualenvs/XiAnMini/lib/python3.6/site-packages/django/core/handlers/base.py", line 124, in _get_response
    response = wrapped_callback(request, *callback_args, **callback_kwargs)
  File "/home/damon96/.virtualenvs/XiAnMini/lib/python3.6/site-packages/django/views/decorators/csrf.py", line 54, in wrapped_view
    return view_func(*args, **kwargs)
  File "/home/damon96/.virtualenvs/XiAnMini/lib/python3.6/site-packages/django/views/decorators/csrf.py", line 54, in wrapped_view
    return view_func(*args, **kwargs)
  File "/home/damon96/.virtualenvs/XiAnMini/lib/python3.6/site-packages/django/views/generic/base.py", line 68, in view
    return self.dispatch(request, *args, **kwargs)
  File "/home/damon96/.virtualenvs/XiAnMini/lib/python3.6/site-packages/rest_framework/views.py", line 495, in dispatch
    response = self.handle_exception(exc)
  File "/home/damon96/.virtualenvs/XiAnMini/lib/python3.6/site-packages/rest_framework/views.py", line 455, in handle_exception
    self.raise_uncaught_exception(exc)
  File "/home/damon96/.virtualenvs/XiAnMini/lib/python3.6/site-packages/rest_framework/views.py", line 492, in dispatch
    response = handler(request, *args, **kwargs)
  File "/home/damon96/.virtualenvs/XiAnMini/lib/python3.6/site-packages/rest_framework/decorators.py", line 55, in handler
    return func(*args, **kwargs)
  File "/home/damon96/PycharmProjects/XiAn/apps/projects/views.py", line 25, in proList
    project_qs = Project.objects.filter(**query_params)
  File "/home/damon96/.virtualenvs/XiAnMini/lib/python3.6/site-packages/django/db/models/manager.py", line 82, in manager_method
    return getattr(self.get_queryset(), name)(*args, **kwargs)
  File "/home/damon96/.virtualenvs/XiAnMini/lib/python3.6/site-packages/django/db/models/query.py", line 841, in filter
    return self._filter_or_exclude(False, *args, **kwargs)
  File "/home/damon96/.virtualenvs/XiAnMini/lib/python3.6/site-packages/django/db/models/query.py", line 859, in _filter_or_exclude
    clone.query.add_q(Q(*args, **kwargs))
  File "/home/damon96/.virtualenvs/XiAnMini/lib/python3.6/site-packages/django/db/models/sql/query.py", line 1263, in add_q
    clause, _ = self._add_q(q_object, self.used_aliases)
  File "/home/damon96/.virtualenvs/XiAnMini/lib/python3.6/site-packages/django/db/models/sql/query.py", line 1287, in _add_q
    split_subq=split_subq,
  File "/home/damon96/.virtualenvs/XiAnMini/lib/python3.6/site-packages/django/db/models/sql/query.py", line 1225, in build_filter
    condition = self.build_lookup(lookups, col, value)
  File "/home/damon96/.virtualenvs/XiAnMini/lib/python3.6/site-packages/django/db/models/sql/query.py", line 1096, in build_lookup
    lookup = lookup_class(lhs, rhs)
  File "/home/damon96/.virtualenvs/XiAnMini/lib/python3.6/site-packages/django/db/models/lookups.py", line 20, in __init__
    self.rhs = self.get_prep_lookup()
  File "/home/damon96/.virtualenvs/XiAnMini/lib/python3.6/site-packages/django/db/models/lookups.py", line 70, in get_prep_lookup
    return self.lhs.output_field.get_prep_value(self.rhs)
  File "/home/damon96/.virtualenvs/XiAnMini/lib/python3.6/site-packages/django/db/models/fields/__init__.py", line 1018, in get_prep_value
    return self.to_python(value)
  File "/home/damon96/.virtualenvs/XiAnMini/lib/python3.6/site-packages/django/db/models/fields/__init__.py", line 1011, in to_python
    params={'value': value},
django.core.exceptions.ValidationError: ['’true‘ 必须为 True 或者 False。']
[ERROR] [2019-05-18 14:38:25,036] [log] [log_response] [14608][line:228] Internal Server Error: /api/proList
Traceback (most recent call last):
  File "/home/damon96/.virtualenvs/XiAnMini/lib/python3.6/site-packages/django/core/handlers/exception.py", line 34, in inner
    response = get_response(request)
  File "/home/damon96/.virtualenvs/XiAnMini/lib/python3.6/site-packages/django/core/handlers/base.py", line 126, in _get_response
    response = self.process_exception_by_middleware(e, request)
  File "/home/damon96/.virtualenvs/XiAnMini/lib/python3.6/site-packages/django/core/handlers/base.py", line 124, in _get_response
    response = wrapped_callback(request, *callback_args, **callback_kwargs)
  File "/home/damon96/.virtualenvs/XiAnMini/lib/python3.6/site-packages/django/views/decorators/csrf.py", line 54, in wrapped_view
    return view_func(*args, **kwargs)
  File "/home/damon96/.virtualenvs/XiAnMini/lib/python3.6/site-packages/django/views/decorators/csrf.py", line 54, in wrapped_view
    return view_func(*args, **kwargs)
  File "/home/damon96/.virtualenvs/XiAnMini/lib/python3.6/site-packages/django/views/generic/base.py", line 68, in view
    return self.dispatch(request, *args, **kwargs)
  File "/home/damon96/.virtualenvs/XiAnMini/lib/python3.6/site-packages/rest_framework/views.py", line 495, in dispatch
    response = self.handle_exception(exc)
  File "/home/damon96/.virtualenvs/XiAnMini/lib/python3.6/site-packages/rest_framework/views.py", line 455, in handle_exception
    self.raise_uncaught_exception(exc)
  File "/home/damon96/.virtualenvs/XiAnMini/lib/python3.6/site-packages/rest_framework/views.py", line 492, in dispatch
    response = handler(request, *args, **kwargs)
  File "/home/damon96/.virtualenvs/XiAnMini/lib/python3.6/site-packages/rest_framework/decorators.py", line 55, in handler
    return func(*args, **kwargs)
  File "/home/damon96/PycharmProjects/XiAn/apps/projects/views.py", line 44, in proList
    pro_list_dict=project_qs.values()
AttributeError: 'Page' object has no attribute 'values'
[ERROR] [2019-05-18 14:41:08,544] [log] [log_response] [14759][line:228] Internal Server Error: /api/proList
Traceback (most recent call last):
  File "/home/damon96/.virtualenvs/XiAnMini/lib/python3.6/site-packages/django/core/handlers/exception.py", line 34, in inner
    response = get_response(request)
  File "/home/damon96/.virtualenvs/XiAnMini/lib/python3.6/site-packages/django/core/handlers/base.py", line 156, in _get_response
    response = self.process_exception_by_middleware(e, request)
  File "/home/damon96/.virtualenvs/XiAnMini/lib/python3.6/site-packages/django/core/handlers/base.py", line 154, in _get_response
    response = response.render()
  File "/home/damon96/.virtualenvs/XiAnMini/lib/python3.6/site-packages/django/template/response.py", line 106, in render
    self.content = self.rendered_content
  File "/home/damon96/.virtualenvs/XiAnMini/lib/python3.6/site-packages/rest_framework/response.py", line 72, in rendered_content
    ret = renderer.render(self.data, accepted_media_type, context)
  File "/home/damon96/.virtualenvs/XiAnMini/lib/python3.6/site-packages/rest_framework/renderers.py", line 107, in render
    allow_nan=not self.strict, separators=separators
  File "/home/damon96/.virtualenvs/XiAnMini/lib/python3.6/site-packages/rest_framework/utils/json.py", line 28, in dumps
    return json.dumps(*args, **kwargs)
  File "/usr/lib/python3.6/json/__init__.py", line 238, in dumps
    **kw).encode(obj)
  File "/usr/lib/python3.6/json/encoder.py", line 199, in encode
    chunks = self.iterencode(o, _one_shot=True)
  File "/usr/lib/python3.6/json/encoder.py", line 257, in iterencode
    return _iterencode(o, 0)
  File "/home/damon96/.virtualenvs/XiAnMini/lib/python3.6/site-packages/rest_framework/utils/encoders.py", line 68, in default
    return super(JSONEncoder, self).default(obj)
  File "/usr/lib/python3.6/json/encoder.py", line 180, in default
    o.__class__.__name__)
TypeError: Object of type 'Page' is not JSON serializable
[ERROR] [2019-05-18 14:43:49,198] [log] [log_response] [15019][line:228] Internal Server Error: /api/proList
Traceback (most recent call last):
  File "/home/damon96/.virtualenvs/XiAnMini/lib/python3.6/site-packages/django/core/handlers/exception.py", line 34, in inner
    response = get_response(request)
  File "/home/damon96/.virtualenvs/XiAnMini/lib/python3.6/site-packages/django/core/handlers/base.py", line 126, in _get_response
    response = self.process_exception_by_middleware(e, request)
  File "/home/damon96/.virtualenvs/XiAnMini/lib/python3.6/site-packages/django/core/handlers/base.py", line 124, in _get_response
    response = wrapped_callback(request, *callback_args, **callback_kwargs)
  File "/home/damon96/.virtualenvs/XiAnMini/lib/python3.6/site-packages/django/views/decorators/csrf.py", line 54, in wrapped_view
    return view_func(*args, **kwargs)
  File "/home/damon96/.virtualenvs/XiAnMini/lib/python3.6/site-packages/django/views/decorators/csrf.py", line 54, in wrapped_view
    return view_func(*args, **kwargs)
  File "/home/damon96/.virtualenvs/XiAnMini/lib/python3.6/site-packages/django/views/generic/base.py", line 68, in view
    return self.dispatch(request, *args, **kwargs)
  File "/home/damon96/.virtualenvs/XiAnMini/lib/python3.6/site-packages/rest_framework/views.py", line 495, in dispatch
    response = self.handle_exception(exc)
  File "/home/damon96/.virtualenvs/XiAnMini/lib/python3.6/site-packages/rest_framework/views.py", line 455, in handle_exception
    self.raise_uncaught_exception(exc)
  File "/home/damon96/.virtualenvs/XiAnMini/lib/python3.6/site-packages/rest_framework/views.py", line 492, in dispatch
    response = handler(request, *args, **kwargs)
  File "/home/damon96/.virtualenvs/XiAnMini/lib/python3.6/site-packages/rest_framework/decorators.py", line 55, in handler
    return func(*args, **kwargs)
  File "/home/damon96/PycharmProjects/XiAn/apps/projects/views.py", line 45, in proList
    print(i.values())
AttributeError: 'Project' object has no attribute 'values'
[ERROR] [2019-05-18 14:46:48,421] [log] [log_response] [15327][line:228] Internal Server Error: /api/proList
Traceback (most recent call last):
  File "/home/damon96/.virtualenvs/XiAnMini/lib/python3.6/site-packages/django/core/handlers/exception.py", line 34, in inner
    response = get_response(request)
  File "/home/damon96/.virtualenvs/XiAnMini/lib/python3.6/site-packages/django/core/handlers/base.py", line 126, in _get_response
    response = self.process_exception_by_middleware(e, request)
  File "/home/damon96/.virtualenvs/XiAnMini/lib/python3.6/site-packages/django/core/handlers/base.py", line 124, in _get_response
    response = wrapped_callback(request, *callback_args, **callback_kwargs)
  File "/home/damon96/.virtualenvs/XiAnMini/lib/python3.6/site-packages/django/views/decorators/csrf.py", line 54, in wrapped_view
    return view_func(*args, **kwargs)
  File "/home/damon96/.virtualenvs/XiAnMini/lib/python3.6/site-packages/django/views/decorators/csrf.py", line 54, in wrapped_view
    return view_func(*args, **kwargs)
  File "/home/damon96/.virtualenvs/XiAnMini/lib/python3.6/site-packages/django/views/generic/base.py", line 68, in view
    return self.dispatch(request, *args, **kwargs)
  File "/home/damon96/.virtualenvs/XiAnMini/lib/python3.6/site-packages/rest_framework/views.py", line 495, in dispatch
    response = self.handle_exception(exc)
  File "/home/damon96/.virtualenvs/XiAnMini/lib/python3.6/site-packages/rest_framework/views.py", line 455, in handle_exception
    self.raise_uncaught_exception(exc)
  File "/home/damon96/.virtualenvs/XiAnMini/lib/python3.6/site-packages/rest_framework/views.py", line 492, in dispatch
    response = handler(request, *args, **kwargs)
  File "/home/damon96/.virtualenvs/XiAnMini/lib/python3.6/site-packages/rest_framework/decorators.py", line 55, in handler
    return func(*args, **kwargs)
  File "/home/damon96/PycharmProjects/XiAn/apps/projects/views.py", line 45, in proList
    json_data = serialize('json', i)
  File "/home/damon96/.virtualenvs/XiAnMini/lib/python3.6/site-packages/django/core/serializers/__init__.py", line 128, in serialize
    s.serialize(queryset, **options)
  File "/home/damon96/.virtualenvs/XiAnMini/lib/python3.6/site-packages/django/core/serializers/base.py", line 87, in serialize
    for count, obj in enumerate(queryset, start=1):
TypeError: 'Project' object is not iterable
[ERROR] [2019-05-18 14:48:33,675] [log] [log_response] [15401][line:228] Internal Server Error: /api/proList
Traceback (most recent call last):
  File "/home/damon96/.virtualenvs/XiAnMini/lib/python3.6/site-packages/django/core/handlers/exception.py", line 34, in inner
    response = get_response(request)
  File "/home/damon96/.virtualenvs/XiAnMini/lib/python3.6/site-packages/django/core/handlers/base.py", line 156, in _get_response
    response = self.process_exception_by_middleware(e, request)
  File "/home/damon96/.virtualenvs/XiAnMini/lib/python3.6/site-packages/django/core/handlers/base.py", line 154, in _get_response
    response = response.render()
  File "/home/damon96/.virtualenvs/XiAnMini/lib/python3.6/site-packages/django/template/response.py", line 106, in render
    self.content = self.rendered_content
  File "/home/damon96/.virtualenvs/XiAnMini/lib/python3.6/site-packages/rest_framework/response.py", line 72, in rendered_content
    ret = renderer.render(self.data, accepted_media_type, context)
  File "/home/damon96/.virtualenvs/XiAnMini/lib/python3.6/site-packages/rest_framework/renderers.py", line 107, in render
    allow_nan=not self.strict, separators=separators
  File "/home/damon96/.virtualenvs/XiAnMini/lib/python3.6/site-packages/rest_framework/utils/json.py", line 28, in dumps
    return json.dumps(*args, **kwargs)
  File "/usr/lib/python3.6/json/__init__.py", line 238, in dumps
    **kw).encode(obj)
  File "/usr/lib/python3.6/json/encoder.py", line 199, in encode
    chunks = self.iterencode(o, _one_shot=True)
  File "/usr/lib/python3.6/json/encoder.py", line 257, in iterencode
    return _iterencode(o, 0)
  File "/home/damon96/.virtualenvs/XiAnMini/lib/python3.6/site-packages/rest_framework/utils/encoders.py", line 52, in default
    return obj.decode('utf-8')
UnicodeDecodeError: 'utf-8' codec can't decode byte 0xff in position 0: invalid start byte
[ERROR] [2019-05-18 14:52:22,211] [log] [log_response] [15772][line:228] Internal Server Error: /api/proList
Traceback (most recent call last):
  File "/home/damon96/.virtualenvs/XiAnMini/lib/python3.6/site-packages/django/core/handlers/exception.py", line 34, in inner
    response = get_response(request)
  File "/home/damon96/.virtualenvs/XiAnMini/lib/python3.6/site-packages/django/core/handlers/base.py", line 126, in _get_response
    response = self.process_exception_by_middleware(e, request)
  File "/home/damon96/.virtualenvs/XiAnMini/lib/python3.6/site-packages/django/core/handlers/base.py", line 124, in _get_response
    response = wrapped_callback(request, *callback_args, **callback_kwargs)
  File "/home/damon96/.virtualenvs/XiAnMini/lib/python3.6/site-packages/django/views/decorators/csrf.py", line 54, in wrapped_view
    return view_func(*args, **kwargs)
  File "/home/damon96/.virtualenvs/XiAnMini/lib/python3.6/site-packages/django/views/decorators/csrf.py", line 54, in wrapped_view
    return view_func(*args, **kwargs)
  File "/home/damon96/.virtualenvs/XiAnMini/lib/python3.6/site-packages/django/views/generic/base.py", line 68, in view
    return self.dispatch(request, *args, **kwargs)
  File "/home/damon96/.virtualenvs/XiAnMini/lib/python3.6/site-packages/rest_framework/views.py", line 495, in dispatch
    response = self.handle_exception(exc)
  File "/home/damon96/.virtualenvs/XiAnMini/lib/python3.6/site-packages/rest_framework/views.py", line 455, in handle_exception
    self.raise_uncaught_exception(exc)
  File "/home/damon96/.virtualenvs/XiAnMini/lib/python3.6/site-packages/rest_framework/views.py", line 492, in dispatch
    response = handler(request, *args, **kwargs)
  File "/home/damon96/.virtualenvs/XiAnMini/lib/python3.6/site-packages/rest_framework/decorators.py", line 55, in handler
    return func(*args, **kwargs)
  File "/home/damon96/PycharmProjects/XiAn/apps/projects/views.py", line 51, in proList
    json_data["logo_img"] = django_settings.XIANFILEPATH + json_data["logo_img"]
TypeError: must be str, not ImageFieldFile
[ERROR] [2019-05-18 14:53:55,854] [log] [log_response] [16028][line:228] Internal Server Error: /api/proList
Traceback (most recent call last):
  File "/home/damon96/.virtualenvs/XiAnMini/lib/python3.6/site-packages/django/core/handlers/exception.py", line 34, in inner
    response = get_response(request)
  File "/home/damon96/.virtualenvs/XiAnMini/lib/python3.6/site-packages/django/core/handlers/base.py", line 126, in _get_response
    response = self.process_exception_by_middleware(e, request)
  File "/home/damon96/.virtualenvs/XiAnMini/lib/python3.6/site-packages/django/core/handlers/base.py", line 124, in _get_response
    response = wrapped_callback(request, *callback_args, **callback_kwargs)
  File "/home/damon96/.virtualenvs/XiAnMini/lib/python3.6/site-packages/django/views/decorators/csrf.py", line 54, in wrapped_view
    return view_func(*args, **kwargs)
  File "/home/damon96/.virtualenvs/XiAnMini/lib/python3.6/site-packages/django/views/decorators/csrf.py", line 54, in wrapped_view
    return view_func(*args, **kwargs)
  File "/home/damon96/.virtualenvs/XiAnMini/lib/python3.6/site-packages/django/views/generic/base.py", line 68, in view
    return self.dispatch(request, *args, **kwargs)
  File "/home/damon96/.virtualenvs/XiAnMini/lib/python3.6/site-packages/rest_framework/views.py", line 495, in dispatch
    response = self.handle_exception(exc)
  File "/home/damon96/.virtualenvs/XiAnMini/lib/python3.6/site-packages/rest_framework/views.py", line 455, in handle_exception
    self.raise_uncaught_exception(exc)
  File "/home/damon96/.virtualenvs/XiAnMini/lib/python3.6/site-packages/rest_framework/views.py", line 492, in dispatch
    response = handler(request, *args, **kwargs)
  File "/home/damon96/.virtualenvs/XiAnMini/lib/python3.6/site-packages/rest_framework/decorators.py", line 55, in handler
    return func(*args, **kwargs)
  File "/home/damon96/PycharmProjects/XiAn/apps/projects/views.py", line 51, in proList
    json_data["logo_img"] = django_settings.XIANFILEPATH + json_data["logo_img"]
TypeError: must be str, not ImageFieldFile
[ERROR] [2019-05-18 15:03:19,412] [log] [log_response] [17014][line:228] Internal Server Error: /api/proList
Traceback (most recent call last):
  File "/home/damon96/.virtualenvs/XiAnMini/lib/python3.6/site-packages/django/db/models/sql/query.py", line 1732, in add_fields
    join_info = self.setup_joins(name.split(LOOKUP_SEP), opts, alias, allow_many=allow_m2m)
  File "/home/damon96/.virtualenvs/XiAnMini/lib/python3.6/site-packages/django/db/models/sql/query.py", line 1473, in setup_joins
    names[:pivot], opts, allow_many, fail_on_missing=True,
  File "/home/damon96/.virtualenvs/XiAnMini/lib/python3.6/site-packages/django/db/models/sql/query.py", line 1389, in names_to_path
    "Choices are: %s" % (name, ", ".join(available)))
django.core.exceptions.FieldError: Cannot resolve keyword 'vedeo' into field. Choices are: id, name, project, project_id, t_created, t_modified, url, video

During handling of the above exception, another exception occurred:

Traceback (most recent call last):
  File "/home/damon96/.virtualenvs/XiAnMini/lib/python3.6/site-packages/django/core/handlers/exception.py", line 34, in inner
    response = get_response(request)
  File "/home/damon96/.virtualenvs/XiAnMini/lib/python3.6/site-packages/django/core/handlers/base.py", line 126, in _get_response
    response = self.process_exception_by_middleware(e, request)
  File "/home/damon96/.virtualenvs/XiAnMini/lib/python3.6/site-packages/django/core/handlers/base.py", line 124, in _get_response
    response = wrapped_callback(request, *callback_args, **callback_kwargs)
  File "/home/damon96/.virtualenvs/XiAnMini/lib/python3.6/site-packages/django/views/decorators/csrf.py", line 54, in wrapped_view
    return view_func(*args, **kwargs)
  File "/home/damon96/.virtualenvs/XiAnMini/lib/python3.6/site-packages/django/views/decorators/csrf.py", line 54, in wrapped_view
    return view_func(*args, **kwargs)
  File "/home/damon96/.virtualenvs/XiAnMini/lib/python3.6/site-packages/django/views/generic/base.py", line 68, in view
    return self.dispatch(request, *args, **kwargs)
  File "/home/damon96/.virtualenvs/XiAnMini/lib/python3.6/site-packages/rest_framework/views.py", line 495, in dispatch
    response = self.handle_exception(exc)
  File "/home/damon96/.virtualenvs/XiAnMini/lib/python3.6/site-packages/rest_framework/views.py", line 455, in handle_exception
    self.raise_uncaught_exception(exc)
  File "/home/damon96/.virtualenvs/XiAnMini/lib/python3.6/site-packages/rest_framework/views.py", line 492, in dispatch
    response = handler(request, *args, **kwargs)
  File "/home/damon96/.virtualenvs/XiAnMini/lib/python3.6/site-packages/rest_framework/decorators.py", line 55, in handler
    return func(*args, **kwargs)
  File "/home/damon96/PycharmProjects/XiAn/apps/projects/views.py", line 53, in proList
    video_list = ProVideo.objects.filter(project=p).values("name","vedeo")
  File "/home/damon96/.virtualenvs/XiAnMini/lib/python3.6/site-packages/django/db/models/query.py", line 747, in values
    clone = self._values(*fields, **expressions)
  File "/home/damon96/.virtualenvs/XiAnMini/lib/python3.6/site-packages/django/db/models/query.py", line 742, in _values
    clone.query.set_values(fields)
  File "/home/damon96/.virtualenvs/XiAnMini/lib/python3.6/site-packages/django/db/models/sql/query.py", line 1984, in set_values
    self.add_fields(field_names, True)
  File "/home/damon96/.virtualenvs/XiAnMini/lib/python3.6/site-packages/django/db/models/sql/query.py", line 1755, in add_fields
    "Choices are: %s" % (name, ", ".join(names)))
django.core.exceptions.FieldError: Cannot resolve keyword 'vedeo' into field. Choices are: id, name, project, project_id, t_created, t_modified, url, video
[ERROR] [2019-05-18 15:14:54,833] [log] [log_response] [18136][line:228] Internal Server Error: /api/proList
Traceback (most recent call last):
  File "/home/damon96/.virtualenvs/XiAnMini/lib/python3.6/site-packages/django/core/handlers/exception.py", line 34, in inner
    response = get_response(request)
  File "/home/damon96/.virtualenvs/XiAnMini/lib/python3.6/site-packages/django/core/handlers/base.py", line 126, in _get_response
    response = self.process_exception_by_middleware(e, request)
  File "/home/damon96/.virtualenvs/XiAnMini/lib/python3.6/site-packages/django/core/handlers/base.py", line 124, in _get_response
    response = wrapped_callback(request, *callback_args, **callback_kwargs)
  File "/home/damon96/.virtualenvs/XiAnMini/lib/python3.6/site-packages/django/views/decorators/csrf.py", line 54, in wrapped_view
    return view_func(*args, **kwargs)
  File "/home/damon96/.virtualenvs/XiAnMini/lib/python3.6/site-packages/django/views/decorators/csrf.py", line 54, in wrapped_view
    return view_func(*args, **kwargs)
  File "/home/damon96/.virtualenvs/XiAnMini/lib/python3.6/site-packages/django/views/generic/base.py", line 68, in view
    return self.dispatch(request, *args, **kwargs)
  File "/home/damon96/.virtualenvs/XiAnMini/lib/python3.6/site-packages/rest_framework/views.py", line 495, in dispatch
    response = self.handle_exception(exc)
  File "/home/damon96/.virtualenvs/XiAnMini/lib/python3.6/site-packages/rest_framework/views.py", line 455, in handle_exception
    self.raise_uncaught_exception(exc)
  File "/home/damon96/.virtualenvs/XiAnMini/lib/python3.6/site-packages/rest_framework/views.py", line 492, in dispatch
    response = handler(request, *args, **kwargs)
  File "/home/damon96/.virtualenvs/XiAnMini/lib/python3.6/site-packages/rest_framework/decorators.py", line 55, in handler
    return func(*args, **kwargs)
  File "/home/damon96/PycharmProjects/XiAn/apps/projects/views.py", line 60, in proList
    json_list["banner_list"] = banner_list
TypeError: list indices must be integers or slices, not str
[ERROR] [2019-05-18 15:14:56,577] [log] [log_response] [18136][line:228] Internal Server Error: /api/proList
Traceback (most recent call last):
  File "/home/damon96/.virtualenvs/XiAnMini/lib/python3.6/site-packages/django/core/handlers/exception.py", line 34, in inner
    response = get_response(request)
  File "/home/damon96/.virtualenvs/XiAnMini/lib/python3.6/site-packages/django/core/handlers/base.py", line 126, in _get_response
    response = self.process_exception_by_middleware(e, request)
  File "/home/damon96/.virtualenvs/XiAnMini/lib/python3.6/site-packages/django/core/handlers/base.py", line 124, in _get_response
    response = wrapped_callback(request, *callback_args, **callback_kwargs)
  File "/home/damon96/.virtualenvs/XiAnMini/lib/python3.6/site-packages/django/views/decorators/csrf.py", line 54, in wrapped_view
    return view_func(*args, **kwargs)
  File "/home/damon96/.virtualenvs/XiAnMini/lib/python3.6/site-packages/django/views/decorators/csrf.py", line 54, in wrapped_view
    return view_func(*args, **kwargs)
  File "/home/damon96/.virtualenvs/XiAnMini/lib/python3.6/site-packages/django/views/generic/base.py", line 68, in view
    return self.dispatch(request, *args, **kwargs)
  File "/home/damon96/.virtualenvs/XiAnMini/lib/python3.6/site-packages/rest_framework/views.py", line 495, in dispatch
    response = self.handle_exception(exc)
  File "/home/damon96/.virtualenvs/XiAnMini/lib/python3.6/site-packages/rest_framework/views.py", line 455, in handle_exception
    self.raise_uncaught_exception(exc)
  File "/home/damon96/.virtualenvs/XiAnMini/lib/python3.6/site-packages/rest_framework/views.py", line 492, in dispatch
    response = handler(request, *args, **kwargs)
  File "/home/damon96/.virtualenvs/XiAnMini/lib/python3.6/site-packages/rest_framework/decorators.py", line 55, in handler
    return func(*args, **kwargs)
  File "/home/damon96/PycharmProjects/XiAn/apps/projects/views.py", line 60, in proList
    json_list["banner_list"] = banner_list
TypeError: list indices must be integers or slices, not str
[ERROR] [2019-05-18 15:27:21,515] [log] [log_response] [19184][line:228] Internal Server Error: /api/proList
Traceback (most recent call last):
  File "/home/damon96/.virtualenvs/XiAnMini/lib/python3.6/site-packages/django/core/handlers/exception.py", line 34, in inner
    response = get_response(request)
  File "/home/damon96/.virtualenvs/XiAnMini/lib/python3.6/site-packages/django/core/handlers/base.py", line 156, in _get_response
    response = self.process_exception_by_middleware(e, request)
  File "/home/damon96/.virtualenvs/XiAnMini/lib/python3.6/site-packages/django/core/handlers/base.py", line 154, in _get_response
    response = response.render()
  File "/home/damon96/.virtualenvs/XiAnMini/lib/python3.6/site-packages/django/template/response.py", line 106, in render
    self.content = self.rendered_content
  File "/home/damon96/.virtualenvs/XiAnMini/lib/python3.6/site-packages/rest_framework/response.py", line 72, in rendered_content
    ret = renderer.render(self.data, accepted_media_type, context)
  File "/home/damon96/.virtualenvs/XiAnMini/lib/python3.6/site-packages/rest_framework/renderers.py", line 107, in render
    allow_nan=not self.strict, separators=separators
  File "/home/damon96/.virtualenvs/XiAnMini/lib/python3.6/site-packages/rest_framework/utils/json.py", line 28, in dumps
    return json.dumps(*args, **kwargs)
  File "/usr/lib/python3.6/json/__init__.py", line 238, in dumps
    **kw).encode(obj)
  File "/usr/lib/python3.6/json/encoder.py", line 199, in encode
    chunks = self.iterencode(o, _one_shot=True)
  File "/usr/lib/python3.6/json/encoder.py", line 257, in iterencode
    return _iterencode(o, 0)
  File "/home/damon96/.virtualenvs/XiAnMini/lib/python3.6/site-packages/rest_framework/utils/encoders.py", line 68, in default
    return super(JSONEncoder, self).default(obj)
  File "/usr/lib/python3.6/json/encoder.py", line 180, in default
    o.__class__.__name__)
TypeError: Object of type 'Country' is not JSON serializable
[ERROR] [2019-05-18 15:47:55,545] [log] [log_response] [20635][line:228] Internal Server Error: /api/proInfo
Traceback (most recent call last):
  File "/home/damon96/.virtualenvs/XiAnMini/lib/python3.6/site-packages/django/core/handlers/exception.py", line 34, in inner
    response = get_response(request)
  File "/home/damon96/.virtualenvs/XiAnMini/lib/python3.6/site-packages/django/core/handlers/base.py", line 126, in _get_response
    response = self.process_exception_by_middleware(e, request)
  File "/home/damon96/.virtualenvs/XiAnMini/lib/python3.6/site-packages/django/core/handlers/base.py", line 124, in _get_response
    response = wrapped_callback(request, *callback_args, **callback_kwargs)
  File "/home/damon96/.virtualenvs/XiAnMini/lib/python3.6/site-packages/django/views/decorators/csrf.py", line 54, in wrapped_view
    return view_func(*args, **kwargs)
  File "/home/damon96/.virtualenvs/XiAnMini/lib/python3.6/site-packages/django/views/decorators/csrf.py", line 54, in wrapped_view
    return view_func(*args, **kwargs)
  File "/home/damon96/.virtualenvs/XiAnMini/lib/python3.6/site-packages/django/views/generic/base.py", line 68, in view
    return self.dispatch(request, *args, **kwargs)
  File "/home/damon96/.virtualenvs/XiAnMini/lib/python3.6/site-packages/rest_framework/views.py", line 495, in dispatch
    response = self.handle_exception(exc)
  File "/home/damon96/.virtualenvs/XiAnMini/lib/python3.6/site-packages/rest_framework/views.py", line 455, in handle_exception
    self.raise_uncaught_exception(exc)
  File "/home/damon96/.virtualenvs/XiAnMini/lib/python3.6/site-packages/rest_framework/views.py", line 492, in dispatch
    response = handler(request, *args, **kwargs)
  File "/home/damon96/.virtualenvs/XiAnMini/lib/python3.6/site-packages/rest_framework/decorators.py", line 55, in handler
    return func(*args, **kwargs)
  File "/home/damon96/PycharmProjects/XiAn/apps/projects/views.py", line 58, in proInfo
    b["img"] = django_settings.XIANFILEPATH + b["img"] if b["video"] else ""
KeyError: 'video'
[WARNING] [2019-05-18 16:08:32,157] [log] [log_response] [22356][line:228] Not Found: /
[ERROR] [2019-05-18 16:08:51,485] [views] [userfav] [22356][line:32] 用户收藏, userid: 1 ，报错原因'Settings' object has no attribute 'ENCRYPT_FIELDS'
[INFO] [2019-05-18 16:08:51,490] [views] [userfav] [22356][line:34] 此时的userfav_dict为{'userid': 1, 'fav_id': '1', 'fav_type': '1'}
[ERROR] [2019-05-18 16:10:20,323] [views] [userfav] [22745][line:31] 用户收藏, userid: 1 ，报错原因Cannot resolve keyword 'userid' into field. Choices are: fav_id, fav_type, id, t_created, t_modified, user_id
[INFO] [2019-05-18 16:10:20,323] [views] [userfav] [22745][line:33] 此时的userfav_dict为{'userid': 1, 'fav_id': '1', 'fav_type': '1'}
[INFO] [2019-05-18 16:10:58,950] [views] [userfav] [22783][line:29] 收藏, userid: 1
[INFO] [2019-05-18 16:10:58,951] [views] [userfav] [22783][line:33] 此时的userfav_dict为{'user_id': 1, 'fav_id': '1', 'fav_type': '1'}
[ERROR] [2019-05-18 16:33:28,046] [log] [log_response] [24728][line:228] Internal Server Error: /api/resourceList
Traceback (most recent call last):
  File "/home/damon96/.virtualenvs/XiAnMini/lib/python3.6/site-packages/django/core/handlers/exception.py", line 34, in inner
    response = get_response(request)
  File "/home/damon96/.virtualenvs/XiAnMini/lib/python3.6/site-packages/django/core/handlers/base.py", line 126, in _get_response
    response = self.process_exception_by_middleware(e, request)
  File "/home/damon96/.virtualenvs/XiAnMini/lib/python3.6/site-packages/django/core/handlers/base.py", line 124, in _get_response
    response = wrapped_callback(request, *callback_args, **callback_kwargs)
  File "/home/damon96/.virtualenvs/XiAnMini/lib/python3.6/site-packages/django/views/decorators/csrf.py", line 54, in wrapped_view
    return view_func(*args, **kwargs)
  File "/home/damon96/.virtualenvs/XiAnMini/lib/python3.6/site-packages/django/views/decorators/csrf.py", line 54, in wrapped_view
    return view_func(*args, **kwargs)
  File "/home/damon96/.virtualenvs/XiAnMini/lib/python3.6/site-packages/django/views/generic/base.py", line 68, in view
    return self.dispatch(request, *args, **kwargs)
  File "/home/damon96/.virtualenvs/XiAnMini/lib/python3.6/site-packages/rest_framework/views.py", line 495, in dispatch
    response = self.handle_exception(exc)
  File "/home/damon96/.virtualenvs/XiAnMini/lib/python3.6/site-packages/rest_framework/views.py", line 455, in handle_exception
    self.raise_uncaught_exception(exc)
  File "/home/damon96/.virtualenvs/XiAnMini/lib/python3.6/site-packages/rest_framework/views.py", line 492, in dispatch
    response = handler(request, *args, **kwargs)
  File "/home/damon96/.virtualenvs/XiAnMini/lib/python3.6/site-packages/rest_framework/decorators.py", line 55, in handler
    return func(*args, **kwargs)
  File "/home/damon96/PycharmProjects/XiAn/apps/operation/views.py", line 67, in resourceList
    res_dict.update({"pro_list": json_list, "country": country})
NameError: name 'country' is not defined
[ERROR] [2019-05-18 16:54:59,463] [views] [rdUser] [26069][line:96] 用户收藏, userid: 1 ，报错原因Cannot resolve keyword 'contact_info' into field. Choices are: fav_id, fav_type, id, t_created, t_modified, user_id
[INFO] [2019-05-18 16:54:59,463] [views] [rdUser] [26069][line:98] 此时的userfav_dict为{'user_id': 1, 'name': '彭志浪', 'contact_info': '15717929717', 'email': '15717929717@163.com', 'is_subscribe': False}
[INFO] [2019-05-18 16:55:45,554] [views] [rdUser] [26207][line:94] 收藏, userid: 1
[INFO] [2019-05-18 16:55:45,555] [views] [rdUser] [26207][line:98] 此时的userfav_dict为{'user_id': 1, 'name': '彭志浪', 'contact_info': '15717929717', 'email': '15717929717@163.com', 'is_subscribe': False}
[INFO] [2019-05-18 17:06:30,107] [views] [appointment] [27481][line:128] 资料下载表单此时的rd_dict为{'user_id': 1, 'name': '彭志浪', 'contact_info': '15717929717', 'email': '15717929717@163.com', 'is_subscribe': False}
[INFO] [2019-05-18 17:07:11,456] [views] [appointment] [27902][line:128] 资料下载表单此时的rd_dict为{'user_id': 1, 'name': '彭志浪', 'contact_info': '15717929717', 'email': '15717929717@163.com', 'is_subscribe': False, 'city': '深圳', 'msg': '看看那个啥'}
[WARNING] [2019-05-19 15:13:19,583] [log] [log_response] [9238][line:228] Method Not Allowed: /api/myfav
[ERROR] [2019-05-19 15:13:24,657] [log] [log_response] [9238][line:228] Internal Server Error: /api/myfav
Traceback (most recent call last):
  File "/home/damon96/.virtualenvs/XiAnMini/lib/python3.6/site-packages/django/core/handlers/exception.py", line 34, in inner
    response = get_response(request)
  File "/home/damon96/.virtualenvs/XiAnMini/lib/python3.6/site-packages/django/core/handlers/base.py", line 126, in _get_response
    response = self.process_exception_by_middleware(e, request)
  File "/home/damon96/.virtualenvs/XiAnMini/lib/python3.6/site-packages/django/core/handlers/base.py", line 124, in _get_response
    response = wrapped_callback(request, *callback_args, **callback_kwargs)
  File "/home/damon96/.virtualenvs/XiAnMini/lib/python3.6/site-packages/django/views/decorators/csrf.py", line 54, in wrapped_view
    return view_func(*args, **kwargs)
  File "/home/damon96/.virtualenvs/XiAnMini/lib/python3.6/site-packages/django/views/decorators/csrf.py", line 54, in wrapped_view
    return view_func(*args, **kwargs)
  File "/home/damon96/.virtualenvs/XiAnMini/lib/python3.6/site-packages/django/views/generic/base.py", line 68, in view
    return self.dispatch(request, *args, **kwargs)
  File "/home/damon96/.virtualenvs/XiAnMini/lib/python3.6/site-packages/rest_framework/views.py", line 495, in dispatch
    response = self.handle_exception(exc)
  File "/home/damon96/.virtualenvs/XiAnMini/lib/python3.6/site-packages/rest_framework/views.py", line 455, in handle_exception
    self.raise_uncaught_exception(exc)
  File "/home/damon96/.virtualenvs/XiAnMini/lib/python3.6/site-packages/rest_framework/views.py", line 492, in dispatch
    response = handler(request, *args, **kwargs)
  File "/home/damon96/.virtualenvs/XiAnMini/lib/python3.6/site-packages/rest_framework/decorators.py", line 55, in handler
    return func(*args, **kwargs)
  File "/home/damon96/PycharmProjects/XiAn/apps/operation/views.py", line 139, in myfav
    user_id = request.jwt_user.id
AttributeError: 'NoneType' object has no attribute 'id'
[ERROR] [2019-05-19 15:13:52,389] [log] [log_response] [9238][line:228] Internal Server Error: /api/myfav
Traceback (most recent call last):
  File "/home/damon96/.virtualenvs/XiAnMini/lib/python3.6/site-packages/django/core/handlers/exception.py", line 34, in inner
    response = get_response(request)
  File "/home/damon96/.virtualenvs/XiAnMini/lib/python3.6/site-packages/django/core/handlers/base.py", line 126, in _get_response
    response = self.process_exception_by_middleware(e, request)
  File "/home/damon96/.virtualenvs/XiAnMini/lib/python3.6/site-packages/django/core/handlers/base.py", line 124, in _get_response
    response = wrapped_callback(request, *callback_args, **callback_kwargs)
  File "/home/damon96/.virtualenvs/XiAnMini/lib/python3.6/site-packages/django/views/decorators/csrf.py", line 54, in wrapped_view
    return view_func(*args, **kwargs)
  File "/home/damon96/.virtualenvs/XiAnMini/lib/python3.6/site-packages/django/views/decorators/csrf.py", line 54, in wrapped_view
    return view_func(*args, **kwargs)
  File "/home/damon96/.virtualenvs/XiAnMini/lib/python3.6/site-packages/django/views/generic/base.py", line 68, in view
    return self.dispatch(request, *args, **kwargs)
  File "/home/damon96/.virtualenvs/XiAnMini/lib/python3.6/site-packages/rest_framework/views.py", line 495, in dispatch
    response = self.handle_exception(exc)
  File "/home/damon96/.virtualenvs/XiAnMini/lib/python3.6/site-packages/rest_framework/views.py", line 455, in handle_exception
    self.raise_uncaught_exception(exc)
  File "/home/damon96/.virtualenvs/XiAnMini/lib/python3.6/site-packages/rest_framework/views.py", line 492, in dispatch
    response = handler(request, *args, **kwargs)
  File "/home/damon96/.virtualenvs/XiAnMini/lib/python3.6/site-packages/rest_framework/decorators.py", line 55, in handler
    return func(*args, **kwargs)
  File "/home/damon96/PycharmProjects/XiAn/apps/operation/views.py", line 139, in myfav
    user_id = request.jwt_user.id
AttributeError: 'NoneType' object has no attribute 'id'
[WARNING] [2019-05-19 15:15:53,864] [log] [log_response] [9404][line:228] Not Found: /favicon.ico
[ERROR] [2019-05-19 15:27:08,701] [log] [log_response] [9404][line:228] Internal Server Error: /api/updateUserInfo
Traceback (most recent call last):
  File "/home/damon96/.virtualenvs/XiAnMini/lib/python3.6/site-packages/django/core/handlers/exception.py", line 34, in inner
    response = get_response(request)
  File "/home/damon96/.virtualenvs/XiAnMini/lib/python3.6/site-packages/django/core/handlers/base.py", line 126, in _get_response
    response = self.process_exception_by_middleware(e, request)
  File "/home/damon96/.virtualenvs/XiAnMini/lib/python3.6/site-packages/django/core/handlers/base.py", line 124, in _get_response
    response = wrapped_callback(request, *callback_args, **callback_kwargs)
  File "/home/damon96/.virtualenvs/XiAnMini/lib/python3.6/site-packages/django/views/decorators/csrf.py", line 54, in wrapped_view
    return view_func(*args, **kwargs)
  File "/home/damon96/.virtualenvs/XiAnMini/lib/python3.6/site-packages/django/views/decorators/csrf.py", line 54, in wrapped_view
    return view_func(*args, **kwargs)
  File "/home/damon96/.virtualenvs/XiAnMini/lib/python3.6/site-packages/django/views/generic/base.py", line 68, in view
    return self.dispatch(request, *args, **kwargs)
  File "/home/damon96/.virtualenvs/XiAnMini/lib/python3.6/site-packages/rest_framework/views.py", line 495, in dispatch
    response = self.handle_exception(exc)
  File "/home/damon96/.virtualenvs/XiAnMini/lib/python3.6/site-packages/rest_framework/views.py", line 455, in handle_exception
    self.raise_uncaught_exception(exc)
  File "/home/damon96/.virtualenvs/XiAnMini/lib/python3.6/site-packages/rest_framework/views.py", line 492, in dispatch
    response = handler(request, *args, **kwargs)
  File "/home/damon96/.virtualenvs/XiAnMini/lib/python3.6/site-packages/rest_framework/decorators.py", line 55, in handler
    return func(*args, **kwargs)
  File "/home/damon96/PycharmProjects/XiAn/apps/users/views.py", line 19, in updateUserInfo
    userid = request.jwt_user.id
AttributeError: 'NoneType' object has no attribute 'id'
[ERROR] [2019-05-19 15:27:31,259] [log] [log_response] [9404][line:228] Internal Server Error: /api/updateUserInfo
Traceback (most recent call last):
  File "/home/damon96/.virtualenvs/XiAnMini/lib/python3.6/site-packages/django/core/handlers/exception.py", line 34, in inner
    response = get_response(request)
  File "/home/damon96/.virtualenvs/XiAnMini/lib/python3.6/site-packages/django/core/handlers/base.py", line 126, in _get_response
    response = self.process_exception_by_middleware(e, request)
  File "/home/damon96/.virtualenvs/XiAnMini/lib/python3.6/site-packages/django/core/handlers/base.py", line 124, in _get_response
    response = wrapped_callback(request, *callback_args, **callback_kwargs)
  File "/home/damon96/.virtualenvs/XiAnMini/lib/python3.6/site-packages/django/views/decorators/csrf.py", line 54, in wrapped_view
    return view_func(*args, **kwargs)
  File "/home/damon96/.virtualenvs/XiAnMini/lib/python3.6/site-packages/django/views/decorators/csrf.py", line 54, in wrapped_view
    return view_func(*args, **kwargs)
  File "/home/damon96/.virtualenvs/XiAnMini/lib/python3.6/site-packages/django/views/generic/base.py", line 68, in view
    return self.dispatch(request, *args, **kwargs)
  File "/home/damon96/.virtualenvs/XiAnMini/lib/python3.6/site-packages/rest_framework/views.py", line 495, in dispatch
    response = self.handle_exception(exc)
  File "/home/damon96/.virtualenvs/XiAnMini/lib/python3.6/site-packages/rest_framework/views.py", line 455, in handle_exception
    self.raise_uncaught_exception(exc)
  File "/home/damon96/.virtualenvs/XiAnMini/lib/python3.6/site-packages/rest_framework/views.py", line 492, in dispatch
    response = handler(request, *args, **kwargs)
  File "/home/damon96/.virtualenvs/XiAnMini/lib/python3.6/site-packages/rest_framework/decorators.py", line 55, in handler
    return func(*args, **kwargs)
  File "/home/damon96/PycharmProjects/XiAn/apps/users/views.py", line 19, in updateUserInfo
    userid = request.jwt_user.id
AttributeError: 'NoneType' object has no attribute 'id'
[ERROR] [2019-05-19 15:27:54,911] [log] [log_response] [9404][line:228] Internal Server Error: /api/updateUserInfo
Traceback (most recent call last):
  File "/home/damon96/.virtualenvs/XiAnMini/lib/python3.6/site-packages/django/core/handlers/exception.py", line 34, in inner
    response = get_response(request)
  File "/home/damon96/.virtualenvs/XiAnMini/lib/python3.6/site-packages/django/core/handlers/base.py", line 126, in _get_response
    response = self.process_exception_by_middleware(e, request)
  File "/home/damon96/.virtualenvs/XiAnMini/lib/python3.6/site-packages/django/core/handlers/base.py", line 124, in _get_response
    response = wrapped_callback(request, *callback_args, **callback_kwargs)
  File "/home/damon96/.virtualenvs/XiAnMini/lib/python3.6/site-packages/django/views/decorators/csrf.py", line 54, in wrapped_view
    return view_func(*args, **kwargs)
  File "/home/damon96/.virtualenvs/XiAnMini/lib/python3.6/site-packages/django/views/decorators/csrf.py", line 54, in wrapped_view
    return view_func(*args, **kwargs)
  File "/home/damon96/.virtualenvs/XiAnMini/lib/python3.6/site-packages/django/views/generic/base.py", line 68, in view
    return self.dispatch(request, *args, **kwargs)
  File "/home/damon96/.virtualenvs/XiAnMini/lib/python3.6/site-packages/rest_framework/views.py", line 495, in dispatch
    response = self.handle_exception(exc)
  File "/home/damon96/.virtualenvs/XiAnMini/lib/python3.6/site-packages/rest_framework/views.py", line 455, in handle_exception
    self.raise_uncaught_exception(exc)
  File "/home/damon96/.virtualenvs/XiAnMini/lib/python3.6/site-packages/rest_framework/views.py", line 492, in dispatch
    response = handler(request, *args, **kwargs)
  File "/home/damon96/.virtualenvs/XiAnMini/lib/python3.6/site-packages/rest_framework/decorators.py", line 55, in handler
    return func(*args, **kwargs)
  File "/home/damon96/PycharmProjects/XiAn/apps/users/views.py", line 19, in updateUserInfo
    userid = request.jwt_user.id
AttributeError: 'NoneType' object has no attribute 'id'
[ERROR] [2019-05-19 15:28:13,978] [log] [log_response] [9404][line:228] Internal Server Error: /api/updateUserInfo
Traceback (most recent call last):
  File "/home/damon96/.virtualenvs/XiAnMini/lib/python3.6/site-packages/django/core/handlers/exception.py", line 34, in inner
    response = get_response(request)
  File "/home/damon96/.virtualenvs/XiAnMini/lib/python3.6/site-packages/django/core/handlers/base.py", line 126, in _get_response
    response = self.process_exception_by_middleware(e, request)
  File "/home/damon96/.virtualenvs/XiAnMini/lib/python3.6/site-packages/django/core/handlers/base.py", line 124, in _get_response
    response = wrapped_callback(request, *callback_args, **callback_kwargs)
  File "/home/damon96/.virtualenvs/XiAnMini/lib/python3.6/site-packages/django/views/decorators/csrf.py", line 54, in wrapped_view
    return view_func(*args, **kwargs)
  File "/home/damon96/.virtualenvs/XiAnMini/lib/python3.6/site-packages/django/views/decorators/csrf.py", line 54, in wrapped_view
    return view_func(*args, **kwargs)
  File "/home/damon96/.virtualenvs/XiAnMini/lib/python3.6/site-packages/django/views/generic/base.py", line 68, in view
    return self.dispatch(request, *args, **kwargs)
  File "/home/damon96/.virtualenvs/XiAnMini/lib/python3.6/site-packages/rest_framework/views.py", line 495, in dispatch
    response = self.handle_exception(exc)
  File "/home/damon96/.virtualenvs/XiAnMini/lib/python3.6/site-packages/rest_framework/views.py", line 455, in handle_exception
    self.raise_uncaught_exception(exc)
  File "/home/damon96/.virtualenvs/XiAnMini/lib/python3.6/site-packages/rest_framework/views.py", line 492, in dispatch
    response = handler(request, *args, **kwargs)
  File "/home/damon96/.virtualenvs/XiAnMini/lib/python3.6/site-packages/rest_framework/decorators.py", line 55, in handler
    return func(*args, **kwargs)
  File "/home/damon96/PycharmProjects/XiAn/apps/users/views.py", line 19, in updateUserInfo
    userid = request.jwt_user.id
AttributeError: 'NoneType' object has no attribute 'id'
[INFO] [2019-05-19 15:28:44,354] [views] [updateUserInfo] [9404][line:24] 此时的userinfo为{'userid': 1, 'city': '深圳'}
[INFO] [2019-05-19 15:28:44,372] [tasks] [updateUserInfoTask] [9404][line:52] 更新用户信息成功, userid: 1
[INFO] [2019-05-19 15:30:11,962] [views] [updateUserInfo] [9404][line:24] 此时的userinfo为{'userid': 1, 'avatarUrl': '彭志浪', 'nickName': '15717929717', 'gender': '15717929717@163.com', 'country': 'false', 'city': '深圳', 'province': '看看那个啥'}
[ERROR] [2019-05-19 15:30:11,964] [tasks] [updateUserInfoTask] [9404][line:54] 更新用户信息失败, userid: 1 ，报错原因invalid literal for int() with base 10: '15717929717@163.com'
[INFO] [2019-05-19 15:32:00,059] [views] [updateUserInfo] [9404][line:24] 此时的userinfo为{'userid': 1, 'avatarUrl': '微信头像', 'nickName': '微信昵称', 'gender': '1', 'country': '中国', 'city': '深圳', 'province': '广东'}
[INFO] [2019-05-19 15:32:00,073] [tasks] [updateUserInfoTask] [9404][line:52] 更新用户信息成功, userid: 1
[WARNING] [2019-05-19 17:04:45,508] [log] [log_response] [9404][line:228] Not Found: /announce
[WARNING] [2019-05-19 17:04:48,519] [log] [log_response] [9404][line:228] Not Found: /announce
[WARNING] [2019-05-19 17:04:57,527] [log] [log_response] [9404][line:228] Not Found: /announce
[WARNING] [2019-05-19 17:05:19,538] [log] [log_response] [9404][line:228] Not Found: /announce
[WARNING] [2019-05-19 17:05:52,547] [log] [log_response] [9404][line:228] Not Found: /announce
[WARNING] [2019-05-19 17:06:43,557] [log] [log_response] [9404][line:228] Not Found: /announce
[WARNING] [2019-05-19 17:07:56,567] [log] [log_response] [9404][line:228] Not Found: /announce
[WARNING] [2019-05-19 17:09:34,578] [log] [log_response] [9404][line:228] Not Found: /announce
[WARNING] [2019-05-19 17:11:43,587] [log] [log_response] [9404][line:228] Not Found: /announce
[WARNING] [2019-05-19 17:14:27,596] [log] [log_response] [9404][line:228] Not Found: /announce
[WARNING] [2019-05-19 17:17:50,618] [log] [log_response] [9404][line:228] Not Found: /announce
[WARNING] [2019-05-19 17:21:55,627] [log] [log_response] [9404][line:228] Not Found: /announce
[WARNING] [2019-05-19 17:26:45,638] [log] [log_response] [9404][line:228] Not Found: /announce
[WARNING] [2019-05-19 17:30:13,155] [log] [log_response] [9404][line:228] Not Found: /announce
[WARNING] [2019-05-19 17:30:15,173] [log] [log_response] [9404][line:228] Not Found: /announce
[WARNING] [2019-05-19 17:30:27,181] [log] [log_response] [9404][line:228] Not Found: /announce
[WARNING] [2019-05-19 17:30:47,191] [log] [log_response] [9404][line:228] Not Found: /announce
[WARNING] [2019-05-19 17:31:22,201] [log] [log_response] [9404][line:228] Not Found: /announce
[WARNING] [2019-05-19 17:32:16,211] [log] [log_response] [9404][line:228] Not Found: /announce
[WARNING] [2019-05-19 17:33:29,219] [log] [log_response] [9404][line:228] Not Found: /announce
[WARNING] [2019-05-19 21:00:15,400] [log] [log_response] [17347][line:228] Method Not Allowed: /api/indexBanner
[WARNING] [2019-05-19 21:01:09,286] [log] [log_response] [17347][line:228] Not Found: /announce
[WARNING] [2019-05-19 21:05:58,308] [log] [log_response] [17347][line:228] Not Found: /announce
[WARNING] [2019-05-19 21:11:01,335] [log] [log_response] [18656][line:228] Not Found: /announce
[WARNING] [2019-05-19 21:16:05,348] [log] [log_response] [19446][line:228] Not Found: /announce
[WARNING] [2019-05-19 21:21:06,354] [log] [log_response] [19446][line:228] Not Found: /announce
[INFO] [2019-05-19 21:53:11,108] [views] [userfav] [5540][line:32] 收藏, userid: 1
[INFO] [2019-05-19 21:53:11,109] [views] [userfav] [5540][line:36] 此时的userfav_dict为{'user_id': 1, 'fav_id': '1', 'fav_type': '2'}
[INFO] [2019-05-19 22:10:05,187] [views] [rdUser] [5759][line:99] 资料下载表单此时的rd_dict为{'user_id': 1, 'name': '彭志浪', 'contact_info': '15717929717', 'email': '15717929717@163.com', 'is_subscribe': False}
[ERROR] [2019-05-24 15:21:35,607] [log] [log_response] [27311][line:228] Internal Server Error: /api/appointment
Traceback (most recent call last):
  File "/home/damon96/.virtualenvs/XiAnMini/lib/python3.6/site-packages/django/core/handlers/exception.py", line 34, in inner
    response = get_response(request)
  File "/home/damon96/.virtualenvs/XiAnMini/lib/python3.6/site-packages/django/core/handlers/base.py", line 126, in _get_response
    response = self.process_exception_by_middleware(e, request)
  File "/home/damon96/.virtualenvs/XiAnMini/lib/python3.6/site-packages/django/core/handlers/base.py", line 124, in _get_response
    response = wrapped_callback(request, *callback_args, **callback_kwargs)
  File "/home/damon96/.virtualenvs/XiAnMini/lib/python3.6/site-packages/django/views/decorators/csrf.py", line 54, in wrapped_view
    return view_func(*args, **kwargs)
  File "/home/damon96/.virtualenvs/XiAnMini/lib/python3.6/site-packages/django/views/decorators/csrf.py", line 54, in wrapped_view
    return view_func(*args, **kwargs)
  File "/home/damon96/.virtualenvs/XiAnMini/lib/python3.6/site-packages/django/views/generic/base.py", line 68, in view
    return self.dispatch(request, *args, **kwargs)
  File "/home/damon96/.virtualenvs/XiAnMini/lib/python3.6/site-packages/rest_framework/views.py", line 495, in dispatch
    response = self.handle_exception(exc)
  File "/home/damon96/.virtualenvs/XiAnMini/lib/python3.6/site-packages/rest_framework/views.py", line 455, in handle_exception
    self.raise_uncaught_exception(exc)
  File "/home/damon96/.virtualenvs/XiAnMini/lib/python3.6/site-packages/rest_framework/views.py", line 492, in dispatch
    response = handler(request, *args, **kwargs)
  File "/home/damon96/.virtualenvs/XiAnMini/lib/python3.6/site-packages/rest_framework/decorators.py", line 55, in handler
    return func(*args, **kwargs)
  File "/home/damon96/PycharmProjects/XiAn/apps/operation/views.py", line 108, in appointment
    user_id = request.jwt_user.id
AttributeError: 'NoneType' object has no attribute 'id'
[WARNING] [2019-05-24 15:25:33,103] [log] [log_response] [27311][line:228] Not Found: /favicon.ico
[ERROR] [2019-05-24 15:26:24,509] [log] [log_response] [27311][line:228] Internal Server Error: /api/appointment
Traceback (most recent call last):
  File "/home/damon96/.virtualenvs/XiAnMini/lib/python3.6/site-packages/django/core/handlers/exception.py", line 34, in inner
    response = get_response(request)
  File "/home/damon96/.virtualenvs/XiAnMini/lib/python3.6/site-packages/django/core/handlers/base.py", line 126, in _get_response
    response = self.process_exception_by_middleware(e, request)
  File "/home/damon96/.virtualenvs/XiAnMini/lib/python3.6/site-packages/django/core/handlers/base.py", line 124, in _get_response
    response = wrapped_callback(request, *callback_args, **callback_kwargs)
  File "/home/damon96/.virtualenvs/XiAnMini/lib/python3.6/site-packages/django/views/decorators/csrf.py", line 54, in wrapped_view
    return view_func(*args, **kwargs)
  File "/home/damon96/.virtualenvs/XiAnMini/lib/python3.6/site-packages/django/views/decorators/csrf.py", line 54, in wrapped_view
    return view_func(*args, **kwargs)
  File "/home/damon96/.virtualenvs/XiAnMini/lib/python3.6/site-packages/django/views/generic/base.py", line 68, in view
    return self.dispatch(request, *args, **kwargs)
  File "/home/damon96/.virtualenvs/XiAnMini/lib/python3.6/site-packages/rest_framework/views.py", line 495, in dispatch
    response = self.handle_exception(exc)
  File "/home/damon96/.virtualenvs/XiAnMini/lib/python3.6/site-packages/rest_framework/views.py", line 455, in handle_exception
    self.raise_uncaught_exception(exc)
  File "/home/damon96/.virtualenvs/XiAnMini/lib/python3.6/site-packages/rest_framework/views.py", line 492, in dispatch
    response = handler(request, *args, **kwargs)
  File "/home/damon96/.virtualenvs/XiAnMini/lib/python3.6/site-packages/rest_framework/decorators.py", line 55, in handler
    return func(*args, **kwargs)
  File "/home/damon96/PycharmProjects/XiAn/apps/operation/views.py", line 108, in appointment
    user_id = request.jwt_user.id
AttributeError: 'NoneType' object has no attribute 'id'
[INFO] [2019-05-24 15:26:43,676] [views] [appointment] [27311][line:130] 资料下载表单此时的rd_dict为{'user_id': 1, 'name': '彭志浪', 'contact_info': '15717929717', 'email': '15717929717@163.com', 'is_subscribe': False, 'city': '深圳', 'msg': '留言'}
[ERROR] [2019-05-24 15:29:47,262] [log] [log_response] [29283][line:228] Internal Server Error: /api/myfav
Traceback (most recent call last):
  File "/home/damon96/.virtualenvs/XiAnMini/lib/python3.6/site-packages/django/core/handlers/exception.py", line 34, in inner
    response = get_response(request)
  File "/home/damon96/.virtualenvs/XiAnMini/lib/python3.6/site-packages/django/core/handlers/base.py", line 126, in _get_response
    response = self.process_exception_by_middleware(e, request)
  File "/home/damon96/.virtualenvs/XiAnMini/lib/python3.6/site-packages/django/core/handlers/base.py", line 124, in _get_response
    response = wrapped_callback(request, *callback_args, **callback_kwargs)
  File "/home/damon96/.virtualenvs/XiAnMini/lib/python3.6/site-packages/django/views/decorators/csrf.py", line 54, in wrapped_view
    return view_func(*args, **kwargs)
  File "/home/damon96/.virtualenvs/XiAnMini/lib/python3.6/site-packages/django/views/decorators/csrf.py", line 54, in wrapped_view
    return view_func(*args, **kwargs)
  File "/home/damon96/.virtualenvs/XiAnMini/lib/python3.6/site-packages/django/views/generic/base.py", line 68, in view
    return self.dispatch(request, *args, **kwargs)
  File "/home/damon96/.virtualenvs/XiAnMini/lib/python3.6/site-packages/rest_framework/views.py", line 495, in dispatch
    response = self.handle_exception(exc)
  File "/home/damon96/.virtualenvs/XiAnMini/lib/python3.6/site-packages/rest_framework/views.py", line 455, in handle_exception
    self.raise_uncaught_exception(exc)
  File "/home/damon96/.virtualenvs/XiAnMini/lib/python3.6/site-packages/rest_framework/views.py", line 492, in dispatch
    response = handler(request, *args, **kwargs)
  File "/home/damon96/.virtualenvs/XiAnMini/lib/python3.6/site-packages/rest_framework/decorators.py", line 55, in handler
    return func(*args, **kwargs)
  File "/home/damon96/PycharmProjects/XiAn/apps/operation/views.py", line 142, in myfav
    user_fav_qs = UserFavorite.objects.filter(user_id=user_id, fav_type=fav_type)
  File "/home/damon96/.virtualenvs/XiAnMini/lib/python3.6/site-packages/django/db/models/manager.py", line 82, in manager_method
    return getattr(self.get_queryset(), name)(*args, **kwargs)
  File "/home/damon96/.virtualenvs/XiAnMini/lib/python3.6/site-packages/django/db/models/query.py", line 841, in filter
    return self._filter_or_exclude(False, *args, **kwargs)
  File "/home/damon96/.virtualenvs/XiAnMini/lib/python3.6/site-packages/django/db/models/query.py", line 859, in _filter_or_exclude
    clone.query.add_q(Q(*args, **kwargs))
  File "/home/damon96/.virtualenvs/XiAnMini/lib/python3.6/site-packages/django/db/models/sql/query.py", line 1263, in add_q
    clause, _ = self._add_q(q_object, self.used_aliases)
  File "/home/damon96/.virtualenvs/XiAnMini/lib/python3.6/site-packages/django/db/models/sql/query.py", line 1287, in _add_q
    split_subq=split_subq,
  File "/home/damon96/.virtualenvs/XiAnMini/lib/python3.6/site-packages/django/db/models/sql/query.py", line 1225, in build_filter
    condition = self.build_lookup(lookups, col, value)
  File "/home/damon96/.virtualenvs/XiAnMini/lib/python3.6/site-packages/django/db/models/sql/query.py", line 1096, in build_lookup
    lookup = lookup_class(lhs, rhs)
  File "/home/damon96/.virtualenvs/XiAnMini/lib/python3.6/site-packages/django/db/models/lookups.py", line 20, in __init__
    self.rhs = self.get_prep_lookup()
  File "/home/damon96/.virtualenvs/XiAnMini/lib/python3.6/site-packages/django/db/models/lookups.py", line 70, in get_prep_lookup
    return self.lhs.output_field.get_prep_value(self.rhs)
  File "/home/damon96/.virtualenvs/XiAnMini/lib/python3.6/site-packages/django/db/models/fields/__init__.py", line 1807, in get_prep_value
    return int(value)
ValueError: invalid literal for int() with base 10: ''
[ERROR] [2019-05-24 15:30:00,635] [log] [log_response] [29283][line:228] Internal Server Error: /api/myfav
Traceback (most recent call last):
  File "/home/damon96/.virtualenvs/XiAnMini/lib/python3.6/site-packages/django/db/backends/utils.py", line 85, in _execute
    return self.cursor.execute(sql, params)
  File "/home/damon96/.virtualenvs/XiAnMini/lib/python3.6/site-packages/django/db/backends/sqlite3/base.py", line 296, in execute
    return Database.Cursor.execute(self, query, params)
sqlite3.OperationalError: no such column: projects_project.longitude

The above exception was the direct cause of the following exception:

Traceback (most recent call last):
  File "/home/damon96/.virtualenvs/XiAnMini/lib/python3.6/site-packages/django/core/handlers/exception.py", line 34, in inner
    response = get_response(request)
  File "/home/damon96/.virtualenvs/XiAnMini/lib/python3.6/site-packages/django/core/handlers/base.py", line 126, in _get_response
    response = self.process_exception_by_middleware(e, request)
  File "/home/damon96/.virtualenvs/XiAnMini/lib/python3.6/site-packages/django/core/handlers/base.py", line 124, in _get_response
    response = wrapped_callback(request, *callback_args, **callback_kwargs)
  File "/home/damon96/.virtualenvs/XiAnMini/lib/python3.6/site-packages/django/views/decorators/csrf.py", line 54, in wrapped_view
    return view_func(*args, **kwargs)
  File "/home/damon96/.virtualenvs/XiAnMini/lib/python3.6/site-packages/django/views/decorators/csrf.py", line 54, in wrapped_view
    return view_func(*args, **kwargs)
  File "/home/damon96/.virtualenvs/XiAnMini/lib/python3.6/site-packages/django/views/generic/base.py", line 68, in view
    return self.dispatch(request, *args, **kwargs)
  File "/home/damon96/.virtualenvs/XiAnMini/lib/python3.6/site-packages/rest_framework/views.py", line 495, in dispatch
    response = self.handle_exception(exc)
  File "/home/damon96/.virtualenvs/XiAnMini/lib/python3.6/site-packages/rest_framework/views.py", line 455, in handle_exception
    self.raise_uncaught_exception(exc)
  File "/home/damon96/.virtualenvs/XiAnMini/lib/python3.6/site-packages/rest_framework/views.py", line 492, in dispatch
    response = handler(request, *args, **kwargs)
  File "/home/damon96/.virtualenvs/XiAnMini/lib/python3.6/site-packages/rest_framework/decorators.py", line 55, in handler
    return func(*args, **kwargs)
  File "/home/damon96/PycharmProjects/XiAn/apps/operation/views.py", line 164, in myfav
    for p in pro_qs:
  File "/home/damon96/.virtualenvs/XiAnMini/lib/python3.6/_collections_abc.py", line 883, in __iter__
    v = self[i]
  File "/home/damon96/.virtualenvs/XiAnMini/lib/python3.6/site-packages/django/core/paginator.py", line 151, in __getitem__
    self.object_list = list(self.object_list)
  File "/home/damon96/.virtualenvs/XiAnMini/lib/python3.6/site-packages/django/db/models/query.py", line 268, in __iter__
    self._fetch_all()
  File "/home/damon96/.virtualenvs/XiAnMini/lib/python3.6/site-packages/django/db/models/query.py", line 1183, in _fetch_all
    self._result_cache = list(self._iterable_class(self))
  File "/home/damon96/.virtualenvs/XiAnMini/lib/python3.6/site-packages/django/db/models/query.py", line 54, in __iter__
    results = compiler.execute_sql(chunked_fetch=self.chunked_fetch, chunk_size=self.chunk_size)
  File "/home/damon96/.virtualenvs/XiAnMini/lib/python3.6/site-packages/django/db/models/sql/compiler.py", line 1061, in execute_sql
    cursor.execute(sql, params)
  File "/home/damon96/.virtualenvs/XiAnMini/lib/python3.6/site-packages/django/db/backends/utils.py", line 100, in execute
    return super().execute(sql, params)
  File "/home/damon96/.virtualenvs/XiAnMini/lib/python3.6/site-packages/django/db/backends/utils.py", line 68, in execute
    return self._execute_with_wrappers(sql, params, many=False, executor=self._execute)
  File "/home/damon96/.virtualenvs/XiAnMini/lib/python3.6/site-packages/django/db/backends/utils.py", line 77, in _execute_with_wrappers
    return executor(sql, params, many, context)
  File "/home/damon96/.virtualenvs/XiAnMini/lib/python3.6/site-packages/django/db/backends/utils.py", line 85, in _execute
    return self.cursor.execute(sql, params)
  File "/home/damon96/.virtualenvs/XiAnMini/lib/python3.6/site-packages/django/db/utils.py", line 89, in __exit__
    raise dj_exc_value.with_traceback(traceback) from exc_value
  File "/home/damon96/.virtualenvs/XiAnMini/lib/python3.6/site-packages/django/db/backends/utils.py", line 85, in _execute
    return self.cursor.execute(sql, params)
  File "/home/damon96/.virtualenvs/XiAnMini/lib/python3.6/site-packages/django/db/backends/sqlite3/base.py", line 296, in execute
    return Database.Cursor.execute(self, query, params)
django.db.utils.OperationalError: no such column: projects_project.longitude
[ERROR] [2019-05-24 15:31:00,529] [log] [log_response] [29283][line:228] Internal Server Error: /api/myfav
Traceback (most recent call last):
  File "/home/damon96/.virtualenvs/XiAnMini/lib/python3.6/site-packages/django/db/backends/utils.py", line 85, in _execute
    return self.cursor.execute(sql, params)
  File "/home/damon96/.virtualenvs/XiAnMini/lib/python3.6/site-packages/django/db/backends/sqlite3/base.py", line 296, in execute
    return Database.Cursor.execute(self, query, params)
sqlite3.OperationalError: no such column: projects_project.longitude

The above exception was the direct cause of the following exception:

Traceback (most recent call last):
  File "/home/damon96/.virtualenvs/XiAnMini/lib/python3.6/site-packages/django/core/handlers/exception.py", line 34, in inner
    response = get_response(request)
  File "/home/damon96/.virtualenvs/XiAnMini/lib/python3.6/site-packages/django/core/handlers/base.py", line 126, in _get_response
    response = self.process_exception_by_middleware(e, request)
  File "/home/damon96/.virtualenvs/XiAnMini/lib/python3.6/site-packages/django/core/handlers/base.py", line 124, in _get_response
    response = wrapped_callback(request, *callback_args, **callback_kwargs)
  File "/home/damon96/.virtualenvs/XiAnMini/lib/python3.6/site-packages/django/views/decorators/csrf.py", line 54, in wrapped_view
    return view_func(*args, **kwargs)
  File "/home/damon96/.virtualenvs/XiAnMini/lib/python3.6/site-packages/django/views/decorators/csrf.py", line 54, in wrapped_view
    return view_func(*args, **kwargs)
  File "/home/damon96/.virtualenvs/XiAnMini/lib/python3.6/site-packages/django/views/generic/base.py", line 68, in view
    return self.dispatch(request, *args, **kwargs)
  File "/home/damon96/.virtualenvs/XiAnMini/lib/python3.6/site-packages/rest_framework/views.py", line 495, in dispatch
    response = self.handle_exception(exc)
  File "/home/damon96/.virtualenvs/XiAnMini/lib/python3.6/site-packages/rest_framework/views.py", line 455, in handle_exception
    self.raise_uncaught_exception(exc)
  File "/home/damon96/.virtualenvs/XiAnMini/lib/python3.6/site-packages/rest_framework/views.py", line 492, in dispatch
    response = handler(request, *args, **kwargs)
  File "/home/damon96/.virtualenvs/XiAnMini/lib/python3.6/site-packages/rest_framework/decorators.py", line 55, in handler
    return func(*args, **kwargs)
  File "/home/damon96/PycharmProjects/XiAn/apps/operation/views.py", line 164, in myfav
    for p in pro_qs:
  File "/home/damon96/.virtualenvs/XiAnMini/lib/python3.6/_collections_abc.py", line 883, in __iter__
    v = self[i]
  File "/home/damon96/.virtualenvs/XiAnMini/lib/python3.6/site-packages/django/core/paginator.py", line 151, in __getitem__
    self.object_list = list(self.object_list)
  File "/home/damon96/.virtualenvs/XiAnMini/lib/python3.6/site-packages/django/db/models/query.py", line 268, in __iter__
    self._fetch_all()
  File "/home/damon96/.virtualenvs/XiAnMini/lib/python3.6/site-packages/django/db/models/query.py", line 1183, in _fetch_all
    self._result_cache = list(self._iterable_class(self))
  File "/home/damon96/.virtualenvs/XiAnMini/lib/python3.6/site-packages/django/db/models/query.py", line 54, in __iter__
    results = compiler.execute_sql(chunked_fetch=self.chunked_fetch, chunk_size=self.chunk_size)
  File "/home/damon96/.virtualenvs/XiAnMini/lib/python3.6/site-packages/django/db/models/sql/compiler.py", line 1061, in execute_sql
    cursor.execute(sql, params)
  File "/home/damon96/.virtualenvs/XiAnMini/lib/python3.6/site-packages/django/db/backends/utils.py", line 100, in execute
    return super().execute(sql, params)
  File "/home/damon96/.virtualenvs/XiAnMini/lib/python3.6/site-packages/django/db/backends/utils.py", line 68, in execute
    return self._execute_with_wrappers(sql, params, many=False, executor=self._execute)
  File "/home/damon96/.virtualenvs/XiAnMini/lib/python3.6/site-packages/django/db/backends/utils.py", line 77, in _execute_with_wrappers
    return executor(sql, params, many, context)
  File "/home/damon96/.virtualenvs/XiAnMini/lib/python3.6/site-packages/django/db/backends/utils.py", line 85, in _execute
    return self.cursor.execute(sql, params)
  File "/home/damon96/.virtualenvs/XiAnMini/lib/python3.6/site-packages/django/db/utils.py", line 89, in __exit__
    raise dj_exc_value.with_traceback(traceback) from exc_value
  File "/home/damon96/.virtualenvs/XiAnMini/lib/python3.6/site-packages/django/db/backends/utils.py", line 85, in _execute
    return self.cursor.execute(sql, params)
  File "/home/damon96/.virtualenvs/XiAnMini/lib/python3.6/site-packages/django/db/backends/sqlite3/base.py", line 296, in execute
    return Database.Cursor.execute(self, query, params)
django.db.utils.OperationalError: no such column: projects_project.longitude
[WARNING] [2019-05-24 15:49:22,920] [log] [log_response] [29283][line:228] Not Found: /announce
[WARNING] [2019-05-31 12:08:44,039] [log] [log_response] [31452][line:228] Not Found: /favicon.ico
[ERROR] [2019-06-02 16:29:08,887] [log] [log_response] [16098][line:228] Internal Server Error: /api/myfav
Traceback (most recent call last):
  File "/home/damon96/.virtualenvs/XiAnMini/lib/python3.6/site-packages/django/core/handlers/exception.py", line 34, in inner
    response = get_response(request)
  File "/home/damon96/.virtualenvs/XiAnMini/lib/python3.6/site-packages/django/core/handlers/base.py", line 126, in _get_response
    response = self.process_exception_by_middleware(e, request)
  File "/home/damon96/.virtualenvs/XiAnMini/lib/python3.6/site-packages/django/core/handlers/base.py", line 124, in _get_response
    response = wrapped_callback(request, *callback_args, **callback_kwargs)
  File "/home/damon96/.virtualenvs/XiAnMini/lib/python3.6/site-packages/django/views/decorators/csrf.py", line 54, in wrapped_view
    return view_func(*args, **kwargs)
  File "/home/damon96/.virtualenvs/XiAnMini/lib/python3.6/site-packages/django/views/decorators/csrf.py", line 54, in wrapped_view
    return view_func(*args, **kwargs)
  File "/home/damon96/.virtualenvs/XiAnMini/lib/python3.6/site-packages/django/views/generic/base.py", line 68, in view
    return self.dispatch(request, *args, **kwargs)
  File "/home/damon96/.virtualenvs/XiAnMini/lib/python3.6/site-packages/rest_framework/views.py", line 495, in dispatch
    response = self.handle_exception(exc)
  File "/home/damon96/.virtualenvs/XiAnMini/lib/python3.6/site-packages/rest_framework/views.py", line 455, in handle_exception
    self.raise_uncaught_exception(exc)
  File "/home/damon96/.virtualenvs/XiAnMini/lib/python3.6/site-packages/rest_framework/views.py", line 492, in dispatch
    response = handler(request, *args, **kwargs)
  File "/home/damon96/.virtualenvs/XiAnMini/lib/python3.6/site-packages/rest_framework/decorators.py", line 55, in handler
    return func(*args, **kwargs)
  File "/home/damon96/PycharmProjects/XiAn/apps/operation/views.py", line 139, in myfav
    user_id = request.jwt_user.id
AttributeError: 'NoneType' object has no attribute 'id'
[WARNING] [2019-07-31 17:46:57,824] [log] [log_response] [1263][line:228] Not Found: /favicon.ico
[ERROR] [2019-07-31 17:47:09,912] [log] [log_response] [1263][line:228] Internal Server Error: /xadmin/projects/project/
Traceback (most recent call last):
  File "/home/damon96/.virtualenvs/XiAnMini/lib/python3.5/site-packages/django/db/backends/utils.py", line 85, in _execute
    return self.cursor.execute(sql, params)
  File "/home/damon96/.virtualenvs/XiAnMini/lib/python3.5/site-packages/django/db/backends/sqlite3/base.py", line 296, in execute
    return Database.Cursor.execute(self, query, params)
sqlite3.OperationalError: no such column: projects_project.gif_img

The above exception was the direct cause of the following exception:

Traceback (most recent call last):
  File "/home/damon96/.virtualenvs/XiAnMini/lib/python3.5/site-packages/django/core/handlers/exception.py", line 34, in inner
    response = get_response(request)
  File "/home/damon96/.virtualenvs/XiAnMini/lib/python3.5/site-packages/django/core/handlers/base.py", line 126, in _get_response
    response = self.process_exception_by_middleware(e, request)
  File "/home/damon96/.virtualenvs/XiAnMini/lib/python3.5/site-packages/django/core/handlers/base.py", line 124, in _get_response
    response = wrapped_callback(request, *callback_args, **callback_kwargs)
  File "/home/damon96/djpro/XiAn/extra_apps/xadmin/sites.py", line 300, in wrapper
    return self.admin_view(view, cacheable)(*args, **kwargs)
  File "/home/damon96/.virtualenvs/XiAnMini/lib/python3.5/site-packages/django/views/decorators/cache.py", line 44, in _wrapped_view_func
    response = view_func(request, *args, **kwargs)
  File "/home/damon96/djpro/XiAn/extra_apps/xadmin/sites.py", line 208, in inner
    return view(request, *args, **kwargs)
  File "/home/damon96/djpro/XiAn/extra_apps/xadmin/views/base.py", line 282, in view
    return handler(request, *args, **kwargs)
  File "/home/damon96/.virtualenvs/XiAnMini/lib/python3.5/site-packages/django/utils/decorators.py", line 45, in _wrapper
    return bound_method(*args, **kwargs)
  File "/home/damon96/.virtualenvs/XiAnMini/lib/python3.5/site-packages/django/utils/decorators.py", line 142, in _wrapped_view
    response = view_func(request, *args, **kwargs)
  File "/home/damon96/djpro/XiAn/extra_apps/xadmin/views/base.py", line 80, in method
    return filter_chain(filters, len(filters) - 1, _inner_method, *args, **kwargs)
  File "/home/damon96/djpro/XiAn/extra_apps/xadmin/views/base.py", line 49, in filter_chain
    return func()
  File "/home/damon96/djpro/XiAn/extra_apps/xadmin/views/base.py", line 74, in _inner_method
    return func(self, *args, **kwargs)
  File "/home/damon96/djpro/XiAn/extra_apps/xadmin/views/list.py", line 401, in get
    response = self.get_result_list()
  File "/home/damon96/djpro/XiAn/extra_apps/xadmin/views/base.py", line 80, in method
    return filter_chain(filters, len(filters) - 1, _inner_method, *args, **kwargs)
  File "/home/damon96/djpro/XiAn/extra_apps/xadmin/views/base.py", line 49, in filter_chain
    return func()
  File "/home/damon96/djpro/XiAn/extra_apps/xadmin/views/base.py", line 74, in _inner_method
    return func(self, *args, **kwargs)
  File "/home/damon96/djpro/XiAn/extra_apps/xadmin/views/list.py", line 200, in get_result_list
    return self.make_result_list()
  File "/home/damon96/djpro/XiAn/extra_apps/xadmin/views/list.py", line 196, in make_result_list
    self.list_per_page * self.page_num + len(self.result_list))
  File "/home/damon96/.virtualenvs/XiAnMini/lib/python3.5/site-packages/django/db/models/query.py", line 250, in __len__
    self._fetch_all()
  File "/home/damon96/.virtualenvs/XiAnMini/lib/python3.5/site-packages/django/db/models/query.py", line 1183, in _fetch_all
    self._result_cache = list(self._iterable_class(self))
  File "/home/damon96/.virtualenvs/XiAnMini/lib/python3.5/site-packages/django/db/models/query.py", line 54, in __iter__
    results = compiler.execute_sql(chunked_fetch=self.chunked_fetch, chunk_size=self.chunk_size)
  File "/home/damon96/.virtualenvs/XiAnMini/lib/python3.5/site-packages/django/db/models/sql/compiler.py", line 1061, in execute_sql
    cursor.execute(sql, params)
  File "/home/damon96/.virtualenvs/XiAnMini/lib/python3.5/site-packages/django/db/backends/utils.py", line 100, in execute
    return super().execute(sql, params)
  File "/home/damon96/.virtualenvs/XiAnMini/lib/python3.5/site-packages/django/db/backends/utils.py", line 68, in execute
    return self._execute_with_wrappers(sql, params, many=False, executor=self._execute)
  File "/home/damon96/.virtualenvs/XiAnMini/lib/python3.5/site-packages/django/db/backends/utils.py", line 77, in _execute_with_wrappers
    return executor(sql, params, many, context)
  File "/home/damon96/.virtualenvs/XiAnMini/lib/python3.5/site-packages/django/db/backends/utils.py", line 85, in _execute
    return self.cursor.execute(sql, params)
  File "/home/damon96/.virtualenvs/XiAnMini/lib/python3.5/site-packages/django/db/utils.py", line 89, in __exit__
    raise dj_exc_value.with_traceback(traceback) from exc_value
  File "/home/damon96/.virtualenvs/XiAnMini/lib/python3.5/site-packages/django/db/backends/utils.py", line 85, in _execute
    return self.cursor.execute(sql, params)
  File "/home/damon96/.virtualenvs/XiAnMini/lib/python3.5/site-packages/django/db/backends/sqlite3/base.py", line 296, in execute
    return Database.Cursor.execute(self, query, params)
django.db.utils.OperationalError: no such column: projects_project.gif_img
[WARNING] [2019-07-31 17:47:38,034] [log] [log_response] [1263][line:228] Not Found: /favicon.ico
[ERROR] [2019-07-31 17:48:18,007] [log] [log_response] [1263][line:228] Internal Server Error: /xadmin/users/company/1/update/
Traceback (most recent call last):
  File "/home/damon96/.virtualenvs/XiAnMini/lib/python3.5/site-packages/django/core/handlers/exception.py", line 34, in inner
    response = get_response(request)
  File "/home/damon96/.virtualenvs/XiAnMini/lib/python3.5/site-packages/django/core/handlers/base.py", line 156, in _get_response
    response = self.process_exception_by_middleware(e, request)
  File "/home/damon96/.virtualenvs/XiAnMini/lib/python3.5/site-packages/django/core/handlers/base.py", line 154, in _get_response
    response = response.render()
  File "/home/damon96/.virtualenvs/XiAnMini/lib/python3.5/site-packages/django/template/response.py", line 106, in render
    self.content = self.rendered_content
  File "/home/damon96/.virtualenvs/XiAnMini/lib/python3.5/site-packages/django/template/response.py", line 83, in rendered_content
    content = template.render(context, self._request)
  File "/home/damon96/.virtualenvs/XiAnMini/lib/python3.5/site-packages/django/template/backends/django.py", line 61, in render
    return self.template.render(context)
  File "/home/damon96/.virtualenvs/XiAnMini/lib/python3.5/site-packages/django/template/base.py", line 171, in render
    return self._render(context)
  File "/home/damon96/.virtualenvs/XiAnMini/lib/python3.5/site-packages/django/template/base.py", line 163, in _render
    return self.nodelist.render(context)
  File "/home/damon96/.virtualenvs/XiAnMini/lib/python3.5/site-packages/django/template/base.py", line 937, in render
    bit = node.render_annotated(context)
  File "/home/damon96/.virtualenvs/XiAnMini/lib/python3.5/site-packages/django/template/base.py", line 904, in render_annotated
    return self.render(context)
  File "/home/damon96/.virtualenvs/XiAnMini/lib/python3.5/site-packages/django/template/loader_tags.py", line 150, in render
    return compiled_parent._render(context)
  File "/home/damon96/.virtualenvs/XiAnMini/lib/python3.5/site-packages/django/template/base.py", line 163, in _render
    return self.nodelist.render(context)
  File "/home/damon96/.virtualenvs/XiAnMini/lib/python3.5/site-packages/django/template/base.py", line 937, in render
    bit = node.render_annotated(context)
  File "/home/damon96/.virtualenvs/XiAnMini/lib/python3.5/site-packages/django/template/base.py", line 904, in render_annotated
    return self.render(context)
  File "/home/damon96/.virtualenvs/XiAnMini/lib/python3.5/site-packages/django/template/loader_tags.py", line 150, in render
    return compiled_parent._render(context)
  File "/home/damon96/.virtualenvs/XiAnMini/lib/python3.5/site-packages/django/template/base.py", line 163, in _render
    return self.nodelist.render(context)
  File "/home/damon96/.virtualenvs/XiAnMini/lib/python3.5/site-packages/django/template/base.py", line 937, in render
    bit = node.render_annotated(context)
  File "/home/damon96/.virtualenvs/XiAnMini/lib/python3.5/site-packages/django/template/base.py", line 904, in render_annotated
    return self.render(context)
  File "/home/damon96/.virtualenvs/XiAnMini/lib/python3.5/site-packages/django/template/loader_tags.py", line 62, in render
    result = block.nodelist.render(context)
  File "/home/damon96/.virtualenvs/XiAnMini/lib/python3.5/site-packages/django/template/base.py", line 937, in render
    bit = node.render_annotated(context)
  File "/home/damon96/.virtualenvs/XiAnMini/lib/python3.5/site-packages/django/template/base.py", line 904, in render_annotated
    return self.render(context)
  File "/home/damon96/.virtualenvs/XiAnMini/lib/python3.5/site-packages/django/template/loader_tags.py", line 62, in render
    result = block.nodelist.render(context)
  File "/home/damon96/.virtualenvs/XiAnMini/lib/python3.5/site-packages/django/template/base.py", line 937, in render
    bit = node.render_annotated(context)
  File "/home/damon96/.virtualenvs/XiAnMini/lib/python3.5/site-packages/django/template/base.py", line 904, in render_annotated
    return self.render(context)
  File "/home/damon96/.virtualenvs/XiAnMini/lib/python3.5/site-packages/crispy_forms/templatetags/crispy_forms_tags.py", line 199, in render
    c = self.get_render(context).flatten()
  File "/home/damon96/.virtualenvs/XiAnMini/lib/python3.5/site-packages/crispy_forms/templatetags/crispy_forms_tags.py", line 118, in get_render
    actual_form.form_html = helper.render_layout(actual_form, node_context, template_pack=self.template_pack)
  File "/home/damon96/.virtualenvs/XiAnMini/lib/python3.5/site-packages/crispy_forms/helper.py", line 308, in render_layout
    template_pack=template_pack
  File "/home/damon96/.virtualenvs/XiAnMini/lib/python3.5/site-packages/crispy_forms/layout.py", line 140, in render
    return self.get_rendered_fields(form, form_style, context, template_pack, **kwargs)
  File "/home/damon96/.virtualenvs/XiAnMini/lib/python3.5/site-packages/crispy_forms/layout.py", line 104, in get_rendered_fields
    for field in self.fields
  File "/home/damon96/.virtualenvs/XiAnMini/lib/python3.5/site-packages/crispy_forms/layout.py", line 104, in <genexpr>
    for field in self.fields
  File "/home/damon96/.virtualenvs/XiAnMini/lib/python3.5/site-packages/crispy_forms/utils.py", line 62, in render_field
    form, form_style, context, template_pack=template_pack,
  File "/home/damon96/.virtualenvs/XiAnMini/lib/python3.5/site-packages/crispy_forms/layout.py", line 361, in render
    fields = self.get_rendered_fields(form, form_style, context, template_pack, **kwargs)
  File "/home/damon96/.virtualenvs/XiAnMini/lib/python3.5/site-packages/crispy_forms/layout.py", line 104, in get_rendered_fields
    for field in self.fields
  File "/home/damon96/.virtualenvs/XiAnMini/lib/python3.5/site-packages/crispy_forms/layout.py", line 104, in <genexpr>
    for field in self.fields
  File "/home/damon96/.virtualenvs/XiAnMini/lib/python3.5/site-packages/crispy_forms/utils.py", line 62, in render_field
    form, form_style, context, template_pack=template_pack,
  File "/home/damon96/.virtualenvs/XiAnMini/lib/python3.5/site-packages/crispy_forms/layout.py", line 361, in render
    fields = self.get_rendered_fields(form, form_style, context, template_pack, **kwargs)
  File "/home/damon96/.virtualenvs/XiAnMini/lib/python3.5/site-packages/crispy_forms/layout.py", line 104, in get_rendered_fields
    for field in self.fields
  File "/home/damon96/.virtualenvs/XiAnMini/lib/python3.5/site-packages/crispy_forms/layout.py", line 104, in <genexpr>
    for field in self.fields
  File "/home/damon96/.virtualenvs/XiAnMini/lib/python3.5/site-packages/crispy_forms/utils.py", line 62, in render_field
    form, form_style, context, template_pack=template_pack,
  File "/home/damon96/.virtualenvs/XiAnMini/lib/python3.5/site-packages/crispy_forms/layout.py", line 287, in render
    fields = self.get_rendered_fields(form, form_style, context, template_pack, **kwargs)
  File "/home/damon96/.virtualenvs/XiAnMini/lib/python3.5/site-packages/crispy_forms/layout.py", line 104, in get_rendered_fields
    for field in self.fields
  File "/home/damon96/.virtualenvs/XiAnMini/lib/python3.5/site-packages/crispy_forms/layout.py", line 104, in <genexpr>
    for field in self.fields
  File "/home/damon96/.virtualenvs/XiAnMini/lib/python3.5/site-packages/crispy_forms/utils.py", line 148, in render_field
    html = template.render(context)
  File "/home/damon96/.virtualenvs/XiAnMini/lib/python3.5/site-packages/django/template/backends/django.py", line 61, in render
    return self.template.render(context)
  File "/home/damon96/.virtualenvs/XiAnMini/lib/python3.5/site-packages/django/template/base.py", line 171, in render
    return self._render(context)
  File "/home/damon96/.virtualenvs/XiAnMini/lib/python3.5/site-packages/django/template/base.py", line 163, in _render
    return self.nodelist.render(context)
  File "/home/damon96/.virtualenvs/XiAnMini/lib/python3.5/site-packages/django/template/base.py", line 937, in render
    bit = node.render_annotated(context)
  File "/home/damon96/.virtualenvs/XiAnMini/lib/python3.5/site-packages/django/template/base.py", line 904, in render_annotated
    return self.render(context)
  File "/home/damon96/.virtualenvs/XiAnMini/lib/python3.5/site-packages/django/template/defaulttags.py", line 309, in render
    return nodelist.render(context)
  File "/home/damon96/.virtualenvs/XiAnMini/lib/python3.5/site-packages/django/template/base.py", line 937, in render
    bit = node.render_annotated(context)
  File "/home/damon96/.virtualenvs/XiAnMini/lib/python3.5/site-packages/django/template/base.py", line 904, in render_annotated
    return self.render(context)
  File "/home/damon96/.virtualenvs/XiAnMini/lib/python3.5/site-packages/django/template/defaulttags.py", line 309, in render
    return nodelist.render(context)
  File "/home/damon96/.virtualenvs/XiAnMini/lib/python3.5/site-packages/django/template/base.py", line 937, in render
    bit = node.render_annotated(context)
  File "/home/damon96/.virtualenvs/XiAnMini/lib/python3.5/site-packages/django/template/base.py", line 904, in render_annotated
    return self.render(context)
  File "/home/damon96/.virtualenvs/XiAnMini/lib/python3.5/site-packages/django/template/defaulttags.py", line 309, in render
    return nodelist.render(context)
  File "/home/damon96/.virtualenvs/XiAnMini/lib/python3.5/site-packages/django/template/base.py", line 940, in render
    bits.append(str(bit))
  File "/home/damon96/.virtualenvs/XiAnMini/lib/python3.5/site-packages/django/utils/html.py", line 397, in <lambda>
    klass.__str__ = lambda self: mark_safe(klass_str(self))
  File "/home/damon96/.virtualenvs/XiAnMini/lib/python3.5/site-packages/django/forms/boundfield.py", line 33, in __str__
    return self.as_widget()
  File "/home/damon96/.virtualenvs/XiAnMini/lib/python3.5/site-packages/django/forms/boundfield.py", line 93, in as_widget
    renderer=self.form.renderer,
TypeError: render() got an unexpected keyword argument 'renderer'
[WARNING] [2019-08-14 16:54:04,455] [log] [log_response] [12804][line:228] Not Found: /admin/
[WARNING] [2019-08-14 16:54:04,482] [log] [log_response] [12804][line:228] Not Found: /favicon.ico
[WARNING] [2019-08-14 16:55:28,038] [log] [log_response] [13050][line:228] Not Found: /favicon.ico
[WARNING] [2019-08-14 16:58:45,090] [log] [log_response] [13254][line:228] Not Found: /favicon.ico
[WARNING] [2019-08-14 17:02:11,458] [log] [log_response] [13730][line:228] Not Found: /favicon.ico
[WARNING] [2019-08-14 17:10:05,937] [log] [log_response] [14510][line:228] Not Found: /favicon.ico
[WARNING] [2019-12-28 14:37:11,039] [log] [log_response] [14069][line:228] Not Found: /favicon.ico
[WARNING] [2019-12-28 14:37:13,385] [log] [log_response] [14069][line:228] Not Found: /favicon.ico
[WARNING] [2019-12-28 14:46:17,965] [log] [log_response] [14069][line:228] Not Found: /
[WARNING] [2019-12-28 14:46:18,150] [log] [log_response] [14069][line:228] Not Found: /favicon.ico
[ERROR] [2019-12-28 14:49:00,695] [log] [log_response] [15996][line:228] Internal Server Error: /xadmin/activity/activity/
Traceback (most recent call last):
  File "/home/damon96/.virtualenvs/XiAnMini/lib/python3.5/site-packages/django/db/backends/utils.py", line 85, in _execute
    return self.cursor.execute(sql, params)
  File "/home/damon96/.virtualenvs/XiAnMini/lib/python3.5/site-packages/django/db/backends/sqlite3/base.py", line 296, in execute
    return Database.Cursor.execute(self, query, params)
sqlite3.OperationalError: no such table: activity_activity

The above exception was the direct cause of the following exception:

Traceback (most recent call last):
  File "/home/damon96/.virtualenvs/XiAnMini/lib/python3.5/site-packages/django/core/handlers/exception.py", line 34, in inner
    response = get_response(request)
  File "/home/damon96/.virtualenvs/XiAnMini/lib/python3.5/site-packages/django/core/handlers/base.py", line 126, in _get_response
    response = self.process_exception_by_middleware(e, request)
  File "/home/damon96/.virtualenvs/XiAnMini/lib/python3.5/site-packages/django/core/handlers/base.py", line 124, in _get_response
    response = wrapped_callback(request, *callback_args, **callback_kwargs)
  File "/home/damon96/djpro/XiAn/extra_apps/xadmin/sites.py", line 300, in wrapper
    return self.admin_view(view, cacheable)(*args, **kwargs)
  File "/home/damon96/.virtualenvs/XiAnMini/lib/python3.5/site-packages/django/views/decorators/cache.py", line 44, in _wrapped_view_func
    response = view_func(request, *args, **kwargs)
  File "/home/damon96/djpro/XiAn/extra_apps/xadmin/sites.py", line 208, in inner
    return view(request, *args, **kwargs)
  File "/home/damon96/djpro/XiAn/extra_apps/xadmin/views/base.py", line 282, in view
    return handler(request, *args, **kwargs)
  File "/home/damon96/.virtualenvs/XiAnMini/lib/python3.5/site-packages/django/utils/decorators.py", line 45, in _wrapper
    return bound_method(*args, **kwargs)
  File "/home/damon96/.virtualenvs/XiAnMini/lib/python3.5/site-packages/django/utils/decorators.py", line 142, in _wrapped_view
    response = view_func(request, *args, **kwargs)
  File "/home/damon96/djpro/XiAn/extra_apps/xadmin/views/base.py", line 80, in method
    return filter_chain(filters, len(filters) - 1, _inner_method, *args, **kwargs)
  File "/home/damon96/djpro/XiAn/extra_apps/xadmin/views/base.py", line 49, in filter_chain
    return func()
  File "/home/damon96/djpro/XiAn/extra_apps/xadmin/views/base.py", line 74, in _inner_method
    return func(self, *args, **kwargs)
  File "/home/damon96/djpro/XiAn/extra_apps/xadmin/views/list.py", line 401, in get
    response = self.get_result_list()
  File "/home/damon96/djpro/XiAn/extra_apps/xadmin/views/base.py", line 80, in method
    return filter_chain(filters, len(filters) - 1, _inner_method, *args, **kwargs)
  File "/home/damon96/djpro/XiAn/extra_apps/xadmin/views/base.py", line 49, in filter_chain
    return func()
  File "/home/damon96/djpro/XiAn/extra_apps/xadmin/views/base.py", line 74, in _inner_method
    return func(self, *args, **kwargs)
  File "/home/damon96/djpro/XiAn/extra_apps/xadmin/views/list.py", line 200, in get_result_list
    return self.make_result_list()
  File "/home/damon96/djpro/XiAn/extra_apps/xadmin/views/list.py", line 177, in make_result_list
    self.result_count = self.paginator.count
  File "/home/damon96/.virtualenvs/XiAnMini/lib/python3.5/site-packages/django/utils/functional.py", line 37, in __get__
    res = instance.__dict__[self.name] = self.func(instance)
  File "/home/damon96/.virtualenvs/XiAnMini/lib/python3.5/site-packages/django/core/paginator.py", line 87, in count
    return self.object_list.count()
  File "/home/damon96/.virtualenvs/XiAnMini/lib/python3.5/site-packages/django/db/models/query.py", line 383, in count
    return self.query.get_count(using=self.db)
  File "/home/damon96/.virtualenvs/XiAnMini/lib/python3.5/site-packages/django/db/models/sql/query.py", line 498, in get_count
    number = obj.get_aggregation(using, ['__count'])['__count']
  File "/home/damon96/.virtualenvs/XiAnMini/lib/python3.5/site-packages/django/db/models/sql/query.py", line 483, in get_aggregation
    result = compiler.execute_sql(SINGLE)
  File "/home/damon96/.virtualenvs/XiAnMini/lib/python3.5/site-packages/django/db/models/sql/compiler.py", line 1061, in execute_sql
    cursor.execute(sql, params)
  File "/home/damon96/.virtualenvs/XiAnMini/lib/python3.5/site-packages/django/db/backends/utils.py", line 100, in execute
    return super().execute(sql, params)
  File "/home/damon96/.virtualenvs/XiAnMini/lib/python3.5/site-packages/django/db/backends/utils.py", line 68, in execute
    return self._execute_with_wrappers(sql, params, many=False, executor=self._execute)
  File "/home/damon96/.virtualenvs/XiAnMini/lib/python3.5/site-packages/django/db/backends/utils.py", line 77, in _execute_with_wrappers
    return executor(sql, params, many, context)
  File "/home/damon96/.virtualenvs/XiAnMini/lib/python3.5/site-packages/django/db/backends/utils.py", line 85, in _execute
    return self.cursor.execute(sql, params)
  File "/home/damon96/.virtualenvs/XiAnMini/lib/python3.5/site-packages/django/db/utils.py", line 89, in __exit__
    raise dj_exc_value.with_traceback(traceback) from exc_value
  File "/home/damon96/.virtualenvs/XiAnMini/lib/python3.5/site-packages/django/db/backends/utils.py", line 85, in _execute
    return self.cursor.execute(sql, params)
  File "/home/damon96/.virtualenvs/XiAnMini/lib/python3.5/site-packages/django/db/backends/sqlite3/base.py", line 296, in execute
    return Database.Cursor.execute(self, query, params)
django.db.utils.OperationalError: no such table: activity_activity
[ERROR] [2019-12-28 15:22:40,494] [log] [log_response] [20822][line:228] Internal Server Error: /api/signupsheet
Traceback (most recent call last):
  File "/home/damon96/.virtualenvs/XiAnMini/lib/python3.5/site-packages/django/core/handlers/exception.py", line 34, in inner
    response = get_response(request)
  File "/home/damon96/.virtualenvs/XiAnMini/lib/python3.5/site-packages/django/core/handlers/base.py", line 126, in _get_response
    response = self.process_exception_by_middleware(e, request)
  File "/home/damon96/.virtualenvs/XiAnMini/lib/python3.5/site-packages/django/core/handlers/base.py", line 124, in _get_response
    response = wrapped_callback(request, *callback_args, **callback_kwargs)
  File "/home/damon96/.virtualenvs/XiAnMini/lib/python3.5/site-packages/django/views/decorators/csrf.py", line 54, in wrapped_view
    return view_func(*args, **kwargs)
  File "/home/damon96/.virtualenvs/XiAnMini/lib/python3.5/site-packages/django/views/decorators/csrf.py", line 54, in wrapped_view
    return view_func(*args, **kwargs)
  File "/home/damon96/.virtualenvs/XiAnMini/lib/python3.5/site-packages/django/views/generic/base.py", line 68, in view
    return self.dispatch(request, *args, **kwargs)
  File "/home/damon96/.virtualenvs/XiAnMini/lib/python3.5/site-packages/rest_framework/views.py", line 495, in dispatch
    response = self.handle_exception(exc)
  File "/home/damon96/.virtualenvs/XiAnMini/lib/python3.5/site-packages/rest_framework/views.py", line 455, in handle_exception
    self.raise_uncaught_exception(exc)
  File "/home/damon96/.virtualenvs/XiAnMini/lib/python3.5/site-packages/rest_framework/views.py", line 492, in dispatch
    response = handler(request, *args, **kwargs)
  File "/home/damon96/.virtualenvs/XiAnMini/lib/python3.5/site-packages/rest_framework/decorators.py", line 55, in handler
    return func(*args, **kwargs)
  File "/home/damon96/djpro/XiAn/apps/activity/views.py", line 36, in signupsheet
    user_id = request.jwt_user.id
AttributeError: 'NoneType' object has no attribute 'id'
[INFO] [2019-12-28 15:32:16,226] [views] [signupsheet] [22048][line:55] 提交活动此时的rd_dict为{'email': '15717929717@163.com', 'user_id': 1, 'contact_info': '15717929717', 'activity_id': '1', 'name': '彭志浪'}
[INFO] [2019-12-28 15:32:46,522] [views] [signupsheet] [22048][line:55] 提交活动此时的rd_dict为{'email': '15717929717@163.com', 'user_id': 1, 'contact_info': '15717929717', 'activity_id': '1', 'name': '彭志浪'}
[INFO] [2019-12-28 15:32:52,227] [views] [signupsheet] [22048][line:55] 提交活动此时的rd_dict为{'activity_id': '1', 'user_id': 1, 'contact_info': '15717929717', 'name': '彭志浪'}
[INFO] [2019-12-28 15:32:57,594] [views] [signupsheet] [22048][line:55] 提交活动此时的rd_dict为{'user_id': 1, 'contact_info': '15717929717', 'name': '彭志浪'}
[INFO] [2019-12-28 15:33:20,860] [views] [signupsheet] [22048][line:55] 提交活动此时的rd_dict为{'email': '15717929717@163.com', 'user_id': 1, 'contact_info': '15717929717', 'activity_id': '1', 'name': '彭志浪'}
[ERROR] [2019-12-28 15:35:07,326] [views] [signupsheet] [22328][line:53] 提交活动, userid: 1 ，报错原因NOT NULL constraint failed: activity_signupsheet.activity_id
[INFO] [2019-12-28 15:35:07,327] [views] [signupsheet] [22328][line:55] 提交活动此时的rd_dict为{'user_id': 1, 'name': '彭志浪', 'contact_info': '15717929717'}
[INFO] [2019-12-28 15:35:24,208] [views] [signupsheet] [22328][line:55] 提交活动此时的rd_dict为{'user_id': 1, 'name': '彭志浪', 'activity_id': '1', 'contact_info': '15717929717'}
[INFO] [2019-12-28 15:35:35,216] [views] [signupsheet] [22328][line:55] 提交活动此时的rd_dict为{'user_id': 1, 'name': '彭志浪', 'activity_id': '1', 'contact_info': '15717929717', 'email': '15717929717@163.com'}
[ERROR] [2020-01-04 14:52:32,459] [log] [log_response] [21771][line:228] Internal Server Error: /api/signupsheet
Traceback (most recent call last):
  File "/home/damon96/.virtualenvs/XiAnMini/lib/python3.5/site-packages/django/core/handlers/exception.py", line 34, in inner
    response = get_response(request)
  File "/home/damon96/.virtualenvs/XiAnMini/lib/python3.5/site-packages/django/core/handlers/base.py", line 126, in _get_response
    response = self.process_exception_by_middleware(e, request)
  File "/home/damon96/.virtualenvs/XiAnMini/lib/python3.5/site-packages/django/core/handlers/base.py", line 124, in _get_response
    response = wrapped_callback(request, *callback_args, **callback_kwargs)
  File "/home/damon96/.virtualenvs/XiAnMini/lib/python3.5/site-packages/django/views/decorators/csrf.py", line 54, in wrapped_view
    return view_func(*args, **kwargs)
  File "/home/damon96/.virtualenvs/XiAnMini/lib/python3.5/site-packages/django/views/decorators/csrf.py", line 54, in wrapped_view
    return view_func(*args, **kwargs)
  File "/home/damon96/.virtualenvs/XiAnMini/lib/python3.5/site-packages/django/views/generic/base.py", line 68, in view
    return self.dispatch(request, *args, **kwargs)
  File "/home/damon96/.virtualenvs/XiAnMini/lib/python3.5/site-packages/rest_framework/views.py", line 495, in dispatch
    response = self.handle_exception(exc)
  File "/home/damon96/.virtualenvs/XiAnMini/lib/python3.5/site-packages/rest_framework/views.py", line 455, in handle_exception
    self.raise_uncaught_exception(exc)
  File "/home/damon96/.virtualenvs/XiAnMini/lib/python3.5/site-packages/rest_framework/views.py", line 492, in dispatch
    response = handler(request, *args, **kwargs)
  File "/home/damon96/.virtualenvs/XiAnMini/lib/python3.5/site-packages/rest_framework/decorators.py", line 55, in handler
    return func(*args, **kwargs)
  File "/home/damon96/djpro/XiAn/apps/activity/views.py", line 36, in signupsheet
    user_id = request.jwt_user.id
AttributeError: 'NoneType' object has no attribute 'id'
[ERROR] [2020-01-04 14:52:58,710] [log] [log_response] [21771][line:228] Internal Server Error: /api/signupsheet
Traceback (most recent call last):
  File "/home/damon96/.virtualenvs/XiAnMini/lib/python3.5/site-packages/django/core/handlers/exception.py", line 34, in inner
    response = get_response(request)
  File "/home/damon96/.virtualenvs/XiAnMini/lib/python3.5/site-packages/django/core/handlers/base.py", line 126, in _get_response
    response = self.process_exception_by_middleware(e, request)
  File "/home/damon96/.virtualenvs/XiAnMini/lib/python3.5/site-packages/django/core/handlers/base.py", line 124, in _get_response
    response = wrapped_callback(request, *callback_args, **callback_kwargs)
  File "/home/damon96/.virtualenvs/XiAnMini/lib/python3.5/site-packages/django/views/decorators/csrf.py", line 54, in wrapped_view
    return view_func(*args, **kwargs)
  File "/home/damon96/.virtualenvs/XiAnMini/lib/python3.5/site-packages/django/views/decorators/csrf.py", line 54, in wrapped_view
    return view_func(*args, **kwargs)
  File "/home/damon96/.virtualenvs/XiAnMini/lib/python3.5/site-packages/django/views/generic/base.py", line 68, in view
    return self.dispatch(request, *args, **kwargs)
  File "/home/damon96/.virtualenvs/XiAnMini/lib/python3.5/site-packages/rest_framework/views.py", line 495, in dispatch
    response = self.handle_exception(exc)
  File "/home/damon96/.virtualenvs/XiAnMini/lib/python3.5/site-packages/rest_framework/views.py", line 455, in handle_exception
    self.raise_uncaught_exception(exc)
  File "/home/damon96/.virtualenvs/XiAnMini/lib/python3.5/site-packages/rest_framework/views.py", line 492, in dispatch
    response = handler(request, *args, **kwargs)
  File "/home/damon96/.virtualenvs/XiAnMini/lib/python3.5/site-packages/rest_framework/decorators.py", line 55, in handler
    return func(*args, **kwargs)
  File "/home/damon96/djpro/XiAn/apps/activity/views.py", line 36, in signupsheet
    user_id = request.jwt_user.id
AttributeError: 'NoneType' object has no attribute 'id'
[INFO] [2020-01-04 14:53:08,453] [views] [signupsheet] [21771][line:55] 提交活动此时的rd_dict为{'user_id': 1, 'name': '彭志浪', 'age': '24', 'contact_info': '15717929717', 'email': '15717929717@163.com', 'activity_id': '1'}
[WARNING] [2020-01-04 15:09:41,363] [log] [log_response] [21771][line:228] Not Found: /admin/
[WARNING] [2020-01-04 15:09:48,241] [log] [log_response] [21771][line:228] Not Found: /admin/
